Workbook

Sheet PTO SUMMARY 2027
A1: PAYROLL'S EDITS ONLY, Password: Payroll | N1: January | S1: February | Y1: March | AD1: Q1 EIB Balancing | AH1: April | AM1: May | AR1: June | AW1: Q2 EIB Balancing | BA1: July | BF1: August | BK1: September | BP1: Q3 EIB Balancing | BT1: October | BY1: November | CD1: December | CJ1: Q4 EIB Balancing
A2: Name | C2: Type | D2: OW? | E2: PTO Plan Code | F2: Loc. | G2: FTE | H2: Monthly Accrual | I2: 2026 EIB Carryover | J2: 2027 EIB Frontload | K2: 1/1/27 EIB Balance | L2: 2026 PTO Carryover | M2: 2027 PTO OW Frontload | N2: Accrued | O2: Used | P2: 01/31/27 Spreadsheet Balance | Q2: 01/31/27 Paycom Balance | R2: Difference | S2: Accrued | T2: Used | U2: PTO Cash Out on 2/20 PR | V2: 02/28/27 Spreadsheet Balance | W2: 02/28/27 Paycom Balance | X2: Difference | Y2: Accrued | Z2: Used | AA2: 03/31/27 Spreadsheet Balance | AB2: 03/31/27 Paycom Balance | AC2: Difference | AD2: Used | AE2: Spreadsheet Balance | AF2: Paycom Balance | AG2: Difference | AH2: Accrued | AI2: Used | AJ2: 04/30/27 Spreadsheet Balance | AK2: 04/30/27 Paycom Balance | AL2: Difference | AM2: Accrued | AN2: Used | AO2: 05/31/27 Spreadsheet Balance | AP2: 05/31/27 Paycom Balance | AQ2: Difference | AR2: Accrued | AS2: Used | AT2: 06/30/27 Spreadsheet Balance | AU2: 06/30/27 Paycom Balance | AV2: Difference | AW2: Used | AX2: Spreadsheet Balance | AY2: Paycom Balance | AZ2: Difference | BA2: Accrued | BB2: Used | BC2: 07/31/27 Spreadsheet Balance | BD2: 07/31/27 Paycom Balance | BE2: Difference | BF2: Accrued | BG2: Used | BH2: 08/31/27 Spreadsheet Balance | BI2: 08/31/27 Paycom Balance | BJ2: Difference | BK2: Accrued | BL2: Used | BM2: 09/30/27 Spreadsheet Balance | BN2: 09/30/27 Paycom Balance | BO2: Difference | BP2: Used | BQ2: Spreadsheet Balance | BR2: Paycom Balance | BS2: Difference | BT2: Accrued | BU2: Used | BV2: 10/31/27 Spreadsheet Balance | BW2: 10/31/27 Paycom Balance | BX2: Difference | BY2: Accrued | BZ2: Used | CA2: 11/30/27 Spreadsheet Balance | CB2: 11/30/27 Paycom Balance | CC2: Difference | CD2: Accrued | CE2: Used | CF2: 12/31/27 Spreadsheet Balance | CG2: 01/01/28 Frontload | CH2: 12/31/27 Paycom Balance w/ Frontload | CI2: Difference | CJ2: Used | CK2: Spreadsheet Balance | CL2: 01/01/28 EIB Frontload | CM2: Paycom Balance w/ Frontload | CN2: Difference
A3: Allison, Gina | B3: A1U7 | C3: MD | D3: Y | E3: OWM | F3: TN | G3: 0.87 | H3: 0 | I3: 0 | J3: 0 | K3: 0 | L3: 0 | M3: 0 | N3: =H3 -> 0 | O3: =SUMIF('January 2027'!$B:$B,'PTO SUMMARY 2027'!B3,'January 2027'!$AK:$AK) -> 0 | P3: =L3+M3+N3-O3 -> 0 | Q3: 0 | R3: 0 | S3: =H3 -> 0 | T3: =SUMIF('February 2027'!$B:$B,'PTO SUMMARY 2027'!G3,'February 2027'!$AK:$AK) -> 0 | U3: 0 | V3: =P3+S3-T3 -> 0 | W3: 0 | X3: 0 | Y3: =H3 -> 0 | Z3: =SUMIF('March 2027'!$B:$B,'PTO SUMMARY 2027'!M3,'March 2027'!$AK:$AK) -> 0 | AA3: =V3+Y3-Z3 -> 0 | AB3: 0 | AC3: 0 | AD3: 0 | AE3: =K3-AD3 -> 0 | AF3: 0 | AG3: =AE3-AF3 -> 0 | AH3: =H3 -> 0 | AI3: =SUMIF('April 2027'!$B:$B,'PTO SUMMARY 2027'!V3,'April 2027'!$AK:$AK) -> 0 | AJ3: =AA3+AH3-AI3 -> 0 | AK3: 0 | AL3: 0 | AM3: =H3 -> 0 | AN3: =SUMIF('May 2027'!$B:$B,'PTO SUMMARY 2027'!AA3,'May 2027'!$AK:$AK) -> 0 | AO3: =ROUND((AJ3+AM3-AN3),2) -> 0 | AP3: 0 | AQ3: 0 | AR3: =H3 -> 0 | AS3: =SUMIF('June 2027'!$B:$B,'PTO SUMMARY 2027'!AF3,'June 2027'!$AK:$AK) -> 0 | AT3: =AO3+AR3-AS3 -> 0 | AU3: 0 | AV3: 0 | AW3: 0 | AX3: 0 | AY3: 0 | AZ3: =AX3-AY3 -> 0 | BA3: =H3 -> 0 | BB3: =SUMIF('July 2027'!$B:$B,'PTO SUMMARY 2027'!AK3,'July 2027'!$AK:$AK) -> 0 | BC3: =AT3+BA3-BB3 -> 0 | BD3: 0 | BE3: 0 | BF3: =H3 -> 0 | BG3: =SUMIF('August 2027'!$B:$B,'PTO SUMMARY 2027'!AP3,'August 2027'!$AK:$AK) -> 0 | BH3: =BC3+BF3-BG3 -> 0 | BI3: 0 | BJ3: 0 | BK3: =H3 -> 0 | BL3: =SUMIF('September 2027'!$B:$B,'PTO SUMMARY 2027'!AU3,'September 2027'!$AK:$AK) -> 0 | BM3: =BH3+BK3-BL3 -> 0 | BN3: 0 | BO3: 0 | BP3: 0 | BQ3: 0 | BR3: 0 | BS3: =BQ3-BR3 -> 0 | BT3: =H3 -> 0 | BU3: =SUMIF('October 2027'!$B:$B,'PTO SUMMARY 2027'!BH3,'October 2027'!$AK:$AK) -> 0 | BV3: =BM3+BT3-BU3 -> 0 | BW3: 0 | BX3: 0 | BY3: =H3 -> 0 | BZ3: =SUMIF('November 2027'!$B:$B,'PTO SUMMARY 2027'!BM3,'November 2027'!$AK:$AK) -> 0 | CA3: =BV3+BY3-BZ3 -> 0 | CB3: 0 | CC3: 0 | CD3: =H3 -> 0 | CE3: =SUMIF('December 2027'!$B:$B,'PTO SUMMARY 2027'!$B:$B,'December 2027'!$AK:$AK) -> 0 | CF3: =CA3+CD3-CE3 -> 0 | CG3: 0 | CH3: 0 | CI3: 0 | CJ3: 0 | CK3: 0 | CL3: 0 | CM3: 0 | CN3: =CK3+CL3-CM3 -> 0
A4: Andrews, Brooke | B4: A3N8 | C4: MD | E4: SAM | F4: PKMD | G4: 1 | H4: =((G4*86.67)*2)*(SUMIF('Accrual Rates'!B:B,'PTO SUMMARY 2027'!B4,'Accrual Rates'!G:G)) -> 15.999975 | I4: 0 | J4: 0 | K4: 0 | L4: 0 | M4: 0 | N4: =H4 -> 15.999975 | O4: =SUMIF('January 2027'!$B:$B,'PTO SUMMARY 2027'!B4,'January 2027'!$AK:$AK) -> 0 | P4: =L4+M4+N4-O4 -> 15.999975 | Q4: 0 | R4: 0 | S4: =H4 -> 15.999975 | T4: =SUMIF('February 2027'!$B:$B,'PTO SUMMARY 2027'!G4,'February 2027'!$AK:$AK) -> 0 | U4: 0 | V4: =P4+S4-T4 -> 31.999951 | W4: 0 | X4: 0 | Y4: =H4 -> 15.999975 | Z4: =SUMIF('March 2027'!$B:$B,'PTO SUMMARY 2027'!M4,'March 2027'!$AK:$AK) -> 0 | AA4: =V4+Y4-Z4 -> 47.999926 | AB4: 0 | AC4: 0 | AD4: 0 | AE4: =K4-AD4 -> 0 | AF4: 0 | AG4: =AE4-AF4 -> 0 | AH4: =H4 -> 15.999975 | AI4: =SUMIF('April 2027'!$B:$B,'PTO SUMMARY 2027'!V4,'April 2027'!$AK:$AK) -> 0 | AJ4: =AA4+AH4-AI4 -> 63.999901 | AK4: 0 | AL4: 0 | AM4: =H4 -> 15.999975 | AN4: =SUMIF('May 2027'!$B:$B,'PTO SUMMARY 2027'!AA4,'May 2027'!$AK:$AK) -> 0 | AO4: =ROUND((AJ4+AM4-AN4),2) -> 80 | AP4: 0 | AQ4: 0 | AR4: =H4 -> 15.999975 | AS4: =SUMIF('June 2027'!$B:$B,'PTO SUMMARY 2027'!AF4,'June 2027'!$AK:$AK) -> 0 | AT4: =AO4+AR4-AS4 -> 95.999975 | AU4: 0 | AV4: 0 | AW4: 0 | AX4: 0 | AY4: 0 | AZ4: =AX4-AY4 -> 0 | BA4: =H4 -> 15.999975 | BB4: =SUMIF('July 2027'!$B:$B,'PTO SUMMARY 2027'!AK4,'July 2027'!$AK:$AK) -> 0 | BC4: =AT4+BA4-BB4 -> 111.99995 | BD4: 0 | BE4: 0 | BF4: =H4 -> 15.999975 | BG4: =SUMIF('August 2027'!$B:$B,'PTO SUMMARY 2027'!AP4,'August 2027'!$AK:$AK) -> 0 | BH4: =BC4+BF4-BG4 -> 127.99993 | BI4: 0 | BJ4: 0 | BK4: =H4 -> 15.999975 | BL4: =SUMIF('September 2027'!$B:$B,'PTO SUMMARY 2027'!AU4,'September 2027'!$AK:$AK) -> 0 | BM4: =BH4+BK4-BL4 -> 143.9999 | BN4: 0 | BO4: 0 | BP4: 0 | BQ4: 0 | BR4: 0 | BS4: =BQ4-BR4 -> 0 | BT4: =H4 -> 15.999975 | BU4: =SUMIF('October 2027'!$B:$B,'PTO SUMMARY 2027'!BH4,'October 2027'!$AK:$AK) -> 0 | BV4: =BM4+BT4-BU4 -> 159.99988 | BW4: 0 | BX4: 0 | BY4: =H4 -> 15.999975 | BZ4: =SUMIF('November 2027'!$B:$B,'PTO SUMMARY 2027'!BM4,'November 2027'!$AK:$AK) -> 0 | CA4: =BV4+BY4-BZ4 -> 175.99985 | CB4: 0 | CC4: 0 | CD4: =H4 -> 15.999975 | CE4: =SUMIF('December 2027'!$B:$B,'PTO SUMMARY 2027'!$B:$B,'December 2027'!$AK:$AK) -> 0 | CF4: =CA4+CD4-CE4 -> 191.99983 | CG4: 0 | CH4: 0 | CI4: 0 | CJ4: 0 | CK4: 0 | CL4: 0 | CM4: 0 | CN4: =CK4+CL4-CM4 -> 0
A5: Atkinson, Paige | B5: A1VK | C5: APC | E5: SMA | F5: GW | G5: 1 | H5: =((G5*86.67)*2)*(SUMIF('Accrual Rates'!B:B,'PTO SUMMARY 2027'!B5,'Accrual Rates'!G:G)) -> 17.333307 | I5: 0 | J5: 0 | K5: 0 | L5: 0 | M5: 0 | N5: =H5 -> 17.333307 | O5: =SUMIF('January 2027'!$B:$B,'PTO SUMMARY 2027'!B5,'January 2027'!$AK:$AK) -> 0 | P5: =L5+M5+N5-O5 -> 17.333307 | Q5: 0 | R5: 0 | S5: =H5 -> 17.333307 | T5: =SUMIF('February 2027'!$B:$B,'PTO SUMMARY 2027'!G5,'February 2027'!$AK:$AK) -> 0 | U5: 0 | V5: =P5+S5-T5 -> 34.666613 | W5: 0 | X5: 0 | Y5: =H5 -> 17.333307 | Z5: =SUMIF('March 2027'!$B:$B,'PTO SUMMARY 2027'!M5,'March 2027'!$AK:$AK) -> 0 | AA5: =V5+Y5-Z5 -> 51.99992 | AB5: 0 | AC5: 0 | AD5: 0 | AE5: =K5-AD5 -> 0 | AF5: 0 | AG5: =AE5-AF5 -> 0 | AH5: =H5 -> 17.333307 | AI5: =SUMIF('April 2027'!$B:$B,'PTO SUMMARY 2027'!V5,'April 2027'!$AK:$AK) -> 0 | AJ5: =AA5+AH5-AI5 -> 69.333227 | AK5: 0 | AL5: 0 | AM5: =H5 -> 17.333307 | AN5: =SUMIF('May 2027'!$B:$B,'PTO SUMMARY 2027'!AA5,'May 2027'!$AK:$AK) -> 0 | AO5: =ROUND((AJ5+AM5-AN5),2) -> 86.67 | AP5: 0 | AQ5: 0 | AR5: =H5 -> 17.333307 | AS5: =SUMIF('June 2027'!$B:$B,'PTO SUMMARY 2027'!AF5,'June 2027'!$AK:$AK) -> 0 | AT5: =AO5+AR5-AS5 -> 104.00331 | AU5: 0 | AV5: 0 | AW5: 0 | AX5: 0 | AY5: 0 | AZ5: =AX5-AY5 -> 0 | BA5: =H5 -> 17.333307 | BB5: =SUMIF('July 2027'!$B:$B,'PTO SUMMARY 2027'!AK5,'July 2027'!$AK:$AK) -> 0 | BC5: =AT5+BA5-BB5 -> 121.33661 | BD5: 0 | BE5: 0 | BF5: =H5 -> 17.333307 | BG5: =SUMIF('August 2027'!$B:$B,'PTO SUMMARY 2027'!AP5,'August 2027'!$AK:$AK) -> 0 | BH5: =BC5+BF5-BG5 -> 138.66992 | BI5: 0 | BJ5: 0 | BK5: =H5 -> 17.333307 | BL5: =SUMIF('September 2027'!$B:$B,'PTO SUMMARY 2027'!AU5,'September 2027'!$AK:$AK) -> 0 | BM5: =BH5+BK5-BL5 -> 156.00323 | BN5: 0 | BO5: 0 | BP5: 0 | BQ5: 0 | BR5: 0 | BS5: =BQ5-BR5 -> 0 | BT5: =H5 -> 17.333307 | BU5: =SUMIF('October 2027'!$B:$B,'PTO SUMMARY 2027'!BH5,'October 2027'!$AK:$AK) -> 0 | BV5: =BM5+BT5-BU5 -> 173.33653 | BW5: 0 | BX5: 0 | BY5: =H5 -> 17.333307 | BZ5: =SUMIF('November 2027'!$B:$B,'PTO SUMMARY 2027'!BM5,'November 2027'!$AK:$AK) -> 0 | CA5: =BV5+BY5-BZ5 -> 190.66984 | CB5: 0 | CC5: 0 | CD5: =H5 -> 17.333307 | CE5: =SUMIF('December 2027'!$B:$B,'PTO SUMMARY 2027'!$B:$B,'December 2027'!$AK:$AK) -> 0 | CF5: =CA5+CD5-CE5 -> 208.00315 | CG5: 0 | CH5: 0 | CI5: 0 | CJ5: 0 | CK5: 0 | CL5: 0 | CM5: 0 | CN5: =CK5+CL5-CM5 -> 0
A6: Austin, Allison | B6: A1VN | C6: APC | E6: SMA | F6: BH | G6: 1 | H6: =((G6*86.67)*2)*(SUMIF('Accrual Rates'!B:B,'PTO SUMMARY 2027'!B6,'Accrual Rates'!G:G)) -> 13.333313 | I6: 0 | J6: 0 | K6: 0 | L6: 0 | M6: 0 | N6: =H6 -> 13.333313 | O6: =SUMIF('January 2027'!$B:$B,'PTO SUMMARY 2027'!B6,'January 2027'!$AK:$AK) -> 0 | P6: =L6+M6+N6-O6 -> 13.333313 | Q6: 0 | R6: 0 | S6: =H6 -> 13.333313 | T6: =SUMIF('February 2027'!$B:$B,'PTO SUMMARY 2027'!G6,'February 2027'!$AK:$AK) -> 0 | U6: 0 | V6: =P6+S6-T6 -> 26.666626 | W6: 0 | X6: 0 | Y6: =H6 -> 13.333313 | Z6: =SUMIF('March 2027'!$B:$B,'PTO SUMMARY 2027'!M6,'March 2027'!$AK:$AK) -> 0 | AA6: =V6+Y6-Z6 -> 39.999938 | AB6: 0 | AC6: 0 | AD6: 0 | AE6: =K6-AD6 -> 0 | AF6: 0 | AG6: =AE6-AF6 -> 0 | AH6: =H6 -> 13.333313 | AI6: =SUMIF('April 2027'!$B:$B,'PTO SUMMARY 2027'!V6,'April 2027'!$AK:$AK) -> 0 | AJ6: =AA6+AH6-AI6 -> 53.333251 | AK6: 0 | AL6: 0 | AM6: =H6 -> 13.333313 | AN6: =SUMIF('May 2027'!$B:$B,'PTO SUMMARY 2027'!AA6,'May 2027'!$AK:$AK) -> 0 | AO6: =ROUND((AJ6+AM6-AN6),2) -> 66.67 | AP6: 0 | AQ6: 0 | AR6: =H6 -> 13.333313 | AS6: =SUMIF('June 2027'!$B:$B,'PTO SUMMARY 2027'!AF6,'June 2027'!$AK:$AK) -> 0 | AT6: =AO6+AR6-AS6 -> 80.003313 | AU6: 0 | AV6: 0 | AW6: 0 | AX6: 0 | AY6: 0 | AZ6: =AX6-AY6 -> 0 | BA6: =H6 -> 13.333313 | BB6: =SUMIF('July 2027'!$B:$B,'PTO SUMMARY 2027'!AK6,'July 2027'!$AK:$AK) -> 0 | BC6: =AT6+BA6-BB6 -> 93.336626 | BD6: 0 | BE6: 0 | BF6: =H6 -> 13.333313 | BG6: =SUMIF('August 2027'!$B:$B,'PTO SUMMARY 2027'!AP6,'August 2027'!$AK:$AK) -> 0 | BH6: =BC6+BF6-BG6 -> 106.66994 | BI6: 0 | BJ6: 0 | BK6: =H6 -> 13.333313 | BL6: =SUMIF('September 2027'!$B:$B,'PTO SUMMARY 2027'!AU6,'September 2027'!$AK:$AK) -> 0 | BM6: =BH6+BK6-BL6 -> 120.00325 | BN6: 0 | BO6: 0 | BP6: 0 | BQ6: 0 | BR6: 0 | BS6: =BQ6-BR6 -> 0 | BT6: =H6 -> 13.333313 | BU6: =SUMIF('October 2027'!$B:$B,'PTO SUMMARY 2027'!BH6,'October 2027'!$AK:$AK) -> 0 | BV6: =BM6+BT6-BU6 -> 133.33656 | BW6: 0 | BX6: 0 | BY6: =H6 -> 13.333313 | BZ6: =SUMIF('November 2027'!$B:$B,'PTO SUMMARY 2027'!BM6,'November 2027'!$AK:$AK) -> 0 | CA6: =BV6+BY6-BZ6 -> 146.66988 | CB6: 0 | CC6: 0 | CD6: =H6 -> 13.333313 | CE6: =SUMIF('December 2027'!$B:$B,'PTO SUMMARY 2027'!$B:$B,'December 2027'!$AK:$AK) -> 0 | CF6: =CA6+CD6-CE6 -> 160.00319 | CG6: 0 | CH6: 0 | CI6: 0 | CJ6: 0 | CK6: 0 | CL6: 0 | CM6: 0 | CN6: =CK6+CL6-CM6 -> 0
A7: Barske, Margaret | B7: A1WH | C7: MD | D7: Y | E7: OWM | F7: NB | G7: 0.875 | H7: 0 | I7: 0 | J7: 0 | K7: 0 | L7: 0 | M7: 0 | N7: =H7 -> 0 | O7: =SUMIF('January 2027'!$B:$B,'PTO SUMMARY 2027'!B7,'January 2027'!$AK:$AK) -> 0 | P7: =L7+M7+N7-O7 -> 0 | Q7: 0 | R7: 0 | S7: =H7 -> 0 | T7: =SUMIF('February 2027'!$B:$B,'PTO SUMMARY 2027'!G7,'February 2027'!$AK:$AK) -> 0 | U7: 0 | V7: =P7+S7-T7 -> 0 | W7: 0 | X7: 0 | Y7: =H7 -> 0 | Z7: =SUMIF('March 2027'!$B:$B,'PTO SUMMARY 2027'!M7,'March 2027'!$AK:$AK) -> 0 | AA7: =V7+Y7-Z7 -> 0 | AB7: 0 | AC7: 0 | AD7: 0 | AE7: =K7-AD7 -> 0 | AF7: 0 | AG7: =AE7-AF7 -> 0 | AH7: =H7 -> 0 | AI7: =SUMIF('April 2027'!$B:$B,'PTO SUMMARY 2027'!V7,'April 2027'!$AK:$AK) -> 0 | AJ7: =AA7+AH7-AI7 -> 0 | AK7: 0 | AL7: 0 | AM7: =H7 -> 0 | AN7: =SUMIF('May 2027'!$B:$B,'PTO SUMMARY 2027'!AA7,'May 2027'!$AK:$AK) -> 0 | AO7: =ROUND((AJ7+AM7-AN7),2) -> 0 | AP7: 0 | AQ7: 0 | AR7: =H7 -> 0 | AS7: =SUMIF('June 2027'!$B:$B,'PTO SUMMARY 2027'!AF7,'June 2027'!$AK:$AK) -> 0 | AT7: =AO7+AR7-AS7 -> 0 | AU7: 0 | AV7: 0 | AW7: 0 | AX7: 0 | AY7: 0 | AZ7: =AX7-AY7 -> 0 | BA7: =H7 -> 0 | BB7: =SUMIF('July 2027'!$B:$B,'PTO SUMMARY 2027'!AK7,'July 2027'!$AK:$AK) -> 0 | BC7: =AT7+BA7-BB7 -> 0 | BD7: 0 | BE7: 0 | BF7: =H7 -> 0 | BG7: =SUMIF('August 2027'!$B:$B,'PTO SUMMARY 2027'!AP7,'August 2027'!$AK:$AK) -> 0 | BH7: =BC7+BF7-BG7 -> 0 | BI7: 0 | BJ7: 0 | BK7: =H7 -> 0 | BL7: =SUMIF('September 2027'!$B:$B,'PTO SUMMARY 2027'!AU7,'September 2027'!$AK:$AK) -> 0 | BM7: =BH7+BK7-BL7 -> 0 | BN7: 0 | BO7: 0 | BP7: 0 | BQ7: 0 | BR7: 0 | BS7: =BQ7-BR7 -> 0 | BT7: =H7 -> 0 | BU7: =SUMIF('October 2027'!$B:$B,'PTO SUMMARY 2027'!BH7,'October 2027'!$AK:$AK) -> 0 | BV7: =BM7+BT7-BU7 -> 0 | BW7: 0 | BX7: 0 | BY7: =H7 -> 0 | BZ7: =SUMIF('November 2027'!$B:$B,'PTO SUMMARY 2027'!BM7,'November 2027'!$AK:$AK) -> 0 | CA7: =BV7+BY7-BZ7 -> 0 | CB7: 0 | CC7: 0 | CD7: =H7 -> 0 | CE7: =SUMIF('December 2027'!$B:$B,'PTO SUMMARY 2027'!$B:$B,'December 2027'!$AK:$AK) -> 0 | CF7: =CA7+CD7-CE7 -> 0 | CG7: 0 | CH7: 0 | CI7: 0 | CJ7: 0 | CK7: 0 | CL7: 0 | CM7: 0 | CN7: =CK7+CL7-CM7 -> 0
A8: Bayne, Lisa | B8: A3PK | C8: MD | E8: SAM | F8: PKMD | G8: 0.75 | H8: =((G8*86.67)*2)*(SUMIF('Accrual Rates'!B:B,'PTO SUMMARY 2027'!B8,'Accrual Rates'!G:G)) -> 9.9999846 | I8: 0 | J8: 0 | K8: 0 | L8: 0 | M8: 0 | N8: =H8 -> 9.9999846 | O8: =SUMIF('January 2027'!$B:$B,'PTO SUMMARY 2027'!B8,'January 2027'!$AK:$AK) -> 0 | P8: =L8+M8+N8-O8 -> 9.9999846 | Q8: 0 | R8: 0 | S8: =H8 -> 9.9999846 | T8: =SUMIF('February 2027'!$B:$B,'PTO SUMMARY 2027'!G8,'February 2027'!$AK:$AK) -> 0 | U8: 0 | V8: =P8+S8-T8 -> 19.999969 | W8: 0 | X8: 0 | Y8: =H8 -> 9.9999846 | Z8: =SUMIF('March 2027'!$B:$B,'PTO SUMMARY 2027'!M8,'March 2027'!$AK:$AK) -> 0 | AA8: =V8+Y8-Z8 -> 29.999954 | AB8: 0 | AC8: 0 | AD8: 0 | AE8: =K8-AD8 -> 0 | AF8: 0 | AG8: =AE8-AF8 -> 0 | AH8: =H8 -> 9.9999846 | AI8: =SUMIF('April 2027'!$B:$B,'PTO SUMMARY 2027'!V8,'April 2027'!$AK:$AK) -> 0 | AJ8: =AA8+AH8-AI8 -> 39.999938 | AK8: 0 | AL8: 0 | AM8: =H8 -> 9.9999846 | AN8: =SUMIF('May 2027'!$B:$B,'PTO SUMMARY 2027'!AA8,'May 2027'!$AK:$AK) -> 0 | AO8: =ROUND((AJ8+AM8-AN8),2) -> 50 | AP8: 0 | AQ8: 0 | AR8: =H8 -> 9.9999846 | AS8: =SUMIF('June 2027'!$B:$B,'PTO SUMMARY 2027'!AF8,'June 2027'!$AK:$AK) -> 0 | AT8: =AO8+AR8-AS8 -> 59.999985 | AU8: 0 | AV8: 0 | AW8: 0 | AX8: 0 | AY8: 0 | AZ8: =AX8-AY8 -> 0 | BA8: =H8 -> 9.9999846 | BB8: =SUMIF('July 2027'!$B:$B,'PTO SUMMARY 2027'!AK8,'July 2027'!$AK:$AK) -> 0 | BC8: =AT8+BA8-BB8 -> 69.999969 | BD8: 0 | BE8: 0 | BF8: =H8 -> 9.9999846 | BG8: =SUMIF('August 2027'!$B:$B,'PTO SUMMARY 2027'!AP8,'August 2027'!$AK:$AK) -> 0 | BH8: =BC8+BF8-BG8 -> 79.999954 | BI8: 0 | BJ8: 0 | BK8: =H8 -> 9.9999846 | BL8: =SUMIF('September 2027'!$B:$B,'PTO SUMMARY 2027'!AU8,'September 2027'!$AK:$AK) -> 0 | BM8: =BH8+BK8-BL8 -> 89.999938 | BN8: 0 | BO8: 0 | BP8: 0 | BQ8: 0 | BR8: 0 | BS8: =BQ8-BR8 -> 0 | BT8: =H8 -> 9.9999846 | BU8: =SUMIF('October 2027'!$B:$B,'PTO SUMMARY 2027'!BH8,'October 2027'!$AK:$AK) -> 0 | BV8: =BM8+BT8-BU8 -> 99.999923 | BW8: 0 | BX8: 0 | BY8: =H8 -> 9.9999846 | BZ8: =SUMIF('November 2027'!$B:$B,'PTO SUMMARY 2027'!BM8,'November 2027'!$AK:$AK) -> 0 | CA8: =BV8+BY8-BZ8 -> 109.99991 | CB8: 0 | CC8: 0 | CD8: =H8 -> 9.9999846 | CE8: =SUMIF('December 2027'!$B:$B,'PTO SUMMARY 2027'!$B:$B,'December 2027'!$AK:$AK) -> 0 | CF8: =CA8+CD8-CE8 -> 119.99989 | CG8: 0 | CH8: 0 | CI8: 0 | CJ8: 0 | CK8: 0 | CL8: 0 | CM8: 0 | CN8: =CK8+CL8-CM8 -> 0
A9: Bennett, Sylvana | B9: A1XP | C9: MD | D9: Y | E9: OWM | F9: NB | G9: 1 | H9: 0 | I9: 0 | J9: 0 | K9: 0 | L9: 0 | M9: 0 | N9: =H9 -> 0 | O9: =SUMIF('January 2027'!$B:$B,'PTO SUMMARY 2027'!B9,'January 2027'!$AK:$AK) -> 0 | P9: =L9+M9+N9-O9 -> 0 | Q9: 0 | R9: 0 | S9: =H9 -> 0 | T9: =SUMIF('February 2027'!$B:$B,'PTO SUMMARY 2027'!G9,'February 2027'!$AK:$AK) -> 0 | U9: 0 | V9: =P9+S9-T9 -> 0 | W9: 0 | X9: 0 | Y9: =H9 -> 0 | Z9: =SUMIF('March 2027'!$B:$B,'PTO SUMMARY 2027'!M9,'March 2027'!$AK:$AK) -> 0 | AA9: =V9+Y9-Z9 -> 0 | AB9: 0 | AC9: 0 | AD9: 0 | AE9: =K9-AD9 -> 0 | AF9: 0 | AG9: =AE9-AF9 -> 0 | AH9: =H9 -> 0 | AI9: =SUMIF('April 2027'!$B:$B,'PTO SUMMARY 2027'!V9,'April 2027'!$AK:$AK) -> 0 | AJ9: =AA9+AH9-AI9 -> 0 | AK9: 0 | AL9: 0 | AM9: =H9 -> 0 | AN9: =SUMIF('May 2027'!$B:$B,'PTO SUMMARY 2027'!AA9,'May 2027'!$AK:$AK) -> 0 | AO9: =ROUND((AJ9+AM9-AN9),2) -> 0 | AP9: 0 | AQ9: 0 | AR9: =H9 -> 0 | AS9: =SUMIF('June 2027'!$B:$B,'PTO SUMMARY 2027'!AF9,'June 2027'!$AK:$AK) -> 0 | AT9: =AO9+AR9-AS9 -> 0 | AU9: 0 | AV9: 0 | AW9: 0 | AX9: 0 | AY9: 0 | AZ9: =AX9-AY9 -> 0 | BA9: =H9 -> 0 | BB9: =SUMIF('July 2027'!$B:$B,'PTO SUMMARY 2027'!AK9,'July 2027'!$AK:$AK) -> 0 | BC9: =AT9+BA9-BB9 -> 0 | BD9: 0 | BE9: 0 | BF9: =H9 -> 0 | BG9: =SUMIF('August 2027'!$B:$B,'PTO SUMMARY 2027'!AP9,'August 2027'!$AK:$AK) -> 0 | BH9: =BC9+BF9-BG9 -> 0 | BI9: 0 | BJ9: 0 | BK9: =H9 -> 0 | BL9: =SUMIF('September 2027'!$B:$B,'PTO SUMMARY 2027'!AU9,'September 2027'!$AK:$AK) -> 0 | BM9: =BH9+BK9-BL9 -> 0 | BN9: 0 | BO9: 0 | BP9: 0 | BQ9: 0 | BR9: 0 | BS9: =BQ9-BR9 -> 0 | BT9: =H9 -> 0 | BU9: =SUMIF('October 2027'!$B:$B,'PTO SUMMARY 2027'!BH9,'October 2027'!$AK:$AK) -> 0 | BV9: =BM9+BT9-BU9 -> 0 | BW9: 0 | BX9: 0 | BY9: =H9 -> 0 | BZ9: =SUMIF('November 2027'!$B:$B,'PTO SUMMARY 2027'!BM9,'November 2027'!$AK:$AK) -> 0 | CA9: =BV9+BY9-BZ9 -> 0 | CB9: 0 | CC9: 0 | CD9: =H9 -> 0 | CE9: =SUMIF('December 2027'!$B:$B,'PTO SUMMARY 2027'!$B:$B,'December 2027'!$AK:$AK) -> 0 | CF9: =CA9+CD9-CE9 -> 0 | CG9: 0 | CH9: 0 | CI9: 0 | CJ9: 0 | CK9: 0 | CL9: 0 | CM9: 0 | CN9: =CK9+CL9-CM9 -> 0
A10: Bircher (Holttum), Jessica | B10: A2IN | C10: MD | D10: Y | E10: OWM | F10: BR | G10: 1 | H10: 0 | I10: 0 | J10: 0 | K10: 0 | L10: 0 | M10: 0 | N10: =H10 -> 0 | O10: =SUMIF('January 2027'!$B:$B,'PTO SUMMARY 2027'!B10,'January 2027'!$AK:$AK) -> 0 | P10: =L10+M10+N10-O10 -> 0 | Q10: 0 | R10: 0 | S10: =H10 -> 0 | T10: =SUMIF('February 2027'!$B:$B,'PTO SUMMARY 2027'!G10,'February 2027'!$AK:$AK) -> 0 | U10: 0 | V10: =P10+S10-T10 -> 0 | W10: 0 | X10: 0 | Y10: =H10 -> 0 | Z10: =SUMIF('March 2027'!$B:$B,'PTO SUMMARY 2027'!M10,'March 2027'!$AK:$AK) -> 0 | AA10: =V10+Y10-Z10 -> 0 | AB10: 0 | AC10: 0 | AD10: 0 | AE10: =K10-AD10 -> 0 | AF10: 0 | AG10: =AE10-AF10 -> 0 | AH10: =H10 -> 0 | AI10: =SUMIF('April 2027'!$B:$B,'PTO SUMMARY 2027'!V10,'April 2027'!$AK:$AK) -> 0 | AJ10: =AA10+AH10-AI10 -> 0 | AK10: 0 | AL10: 0 | AM10: =H10 -> 0 | AN10: =SUMIF('May 2027'!$B:$B,'PTO SUMMARY 2027'!AA10,'May 2027'!$AK:$AK) -> 0 | AO10: =ROUND((AJ10+AM10-AN10),2) -> 0 | AP10: 0 | AQ10: 0 | AR10: =H10 -> 0 | AS10: =SUMIF('June 2027'!$B:$B,'PTO SUMMARY 2027'!AF10,'June 2027'!$AK:$AK) -> 0 | AT10: =AO10+AR10-AS10 -> 0 | AU10: 0 | AV10: 0 | AW10: 0 | AX10: 0 | AY10: 0 | AZ10: =AX10-AY10 -> 0 | BA10: =H10 -> 0 | BB10: =SUMIF('July 2027'!$B:$B,'PTO SUMMARY 2027'!AK10,'July 2027'!$AK:$AK) -> 0 | BC10: =AT10+BA10-BB10 -> 0 | BD10: 0 | BE10: 0 | BF10: =H10 -> 0 | BG10: =SUMIF('August 2027'!$B:$B,'PTO SUMMARY 2027'!AP10,'August 2027'!$AK:$AK) -> 0 | BH10: =BC10+BF10-BG10 -> 0 | BI10: 0 | BJ10: 0 | BK10: =H10 -> 0 | BL10: =SUMIF('September 2027'!$B:$B,'PTO SUMMARY 2027'!AU10,'September 2027'!$AK:$AK) -> 0 | BM10: =BH10+BK10-BL10 -> 0 | BN10: 0 | BO10: 0 | BP10: 0 | BQ10: 0 | BR10: 0 | BS10: =BQ10-BR10 -> 0 | BT10: =H10 -> 0 | BU10: =SUMIF('October 2027'!$B:$B,'PTO SUMMARY 2027'!BH10,'October 2027'!$AK:$AK) -> 0 | BV10: =BM10+BT10-BU10 -> 0 | BW10: 0 | BX10: 0 | BY10: =H10 -> 0 | BZ10: =SUMIF('November 2027'!$B:$B,'PTO SUMMARY 2027'!BM10,'November 2027'!$AK:$AK) -> 0 | CA10: =BV10+BY10-BZ10 -> 0 | CB10: 0 | CC10: 0 | CD10: =H10 -> 0 | CE10: =SUMIF('December 2027'!$B:$B,'PTO SUMMARY 2027'!$B:$B,'December 2027'!$AK:$AK) -> 0 | CF10: =CA10+CD10-CE10 -> 0 | CG10: 0 | CH10: 0 | CI10: 0 | CJ10: 0 | CK10: 0 | CL10: 0 | CM10: 0 | CN10: =CK10+CL10-CM10 -> 0
A11: Bishop, Jennifer | B11: A1YF | C11: APC | E11: SMA | F11: PKMD | G11: 0.8 | H11: =((G11*86.67)*2)*(SUMIF('Accrual Rates'!B:B,'PTO SUMMARY 2027'!B11,'Accrual Rates'!G:G)) -> 13.866645 | I11: 0 | J11: 0 | K11: 0 | L11: 0 | M11: 0 | N11: =H11 -> 13.866645 | O11: =SUMIF('January 2027'!$B:$B,'PTO SUMMARY 2027'!B11,'January 2027'!$AK:$AK) -> 0 | P11: =L11+M11+N11-O11 -> 13.866645 | Q11: 0 | R11: 0 | S11: =H11 -> 13.866645 | T11: =SUMIF('February 2027'!$B:$B,'PTO SUMMARY 2027'!G11,'February 2027'!$AK:$AK) -> 0 | U11: 0 | V11: =P11+S11-T11 -> 27.733291 | W11: 0 | X11: 0 | Y11: =H11 -> 13.866645 | Z11: =SUMIF('March 2027'!$B:$B,'PTO SUMMARY 2027'!M11,'March 2027'!$AK:$AK) -> 0 | AA11: =V11+Y11-Z11 -> 41.599936 | AB11: 0 | AC11: 0 | AD11: 0 | AE11: =K11-AD11 -> 0 | AF11: 0 | AG11: =AE11-AF11 -> 0 | AH11: =H11 -> 13.866645 | AI11: =SUMIF('April 2027'!$B:$B,'PTO SUMMARY 2027'!V11,'April 2027'!$AK:$AK) -> 0 | AJ11: =AA11+AH11-AI11 -> 55.466581 | AK11: 0 | AL11: 0 | AM11: =H11 -> 13.866645 | AN11: =SUMIF('May 2027'!$B:$B,'PTO SUMMARY 2027'!AA11,'May 2027'!$AK:$AK) -> 0 | AO11: =ROUND((AJ11+AM11-AN11),2) -> 69.33 | AP11: 0 | AQ11: 0 | AR11: =H11 -> 13.866645 | AS11: =SUMIF('June 2027'!$B:$B,'PTO SUMMARY 2027'!AF11,'June 2027'!$AK:$AK) -> 0 | AT11: =AO11+AR11-AS11 -> 83.196645 | AU11: 0 | AV11: 0 | AW11: 0 | AX11: 0 | AY11: 0 | AZ11: =AX11-AY11 -> 0 | BA11: =H11 -> 13.866645 | BB11: =SUMIF('July 2027'!$B:$B,'PTO SUMMARY 2027'!AK11,'July 2027'!$AK:$AK) -> 0 | BC11: =AT11+BA11-BB11 -> 97.063291 | BD11: 0 | BE11: 0 | BF11: =H11 -> 13.866645 | BG11: =SUMIF('August 2027'!$B:$B,'PTO SUMMARY 2027'!AP11,'August 2027'!$AK:$AK) -> 0 | BH11: =BC11+BF11-BG11 -> 110.92994 | BI11: 0 | BJ11: 0 | BK11: =H11 -> 13.866645 | BL11: =SUMIF('September 2027'!$B:$B,'PTO SUMMARY 2027'!AU11,'September 2027'!$AK:$AK) -> 0 | BM11: =BH11+BK11-BL11 -> 124.79658 | BN11: 0 | BO11: 0 | BP11: 0 | BQ11: 0 | BR11: 0 | BS11: =BQ11-BR11 -> 0 | BT11: =H11 -> 13.866645 | BU11: =SUMIF('October 2027'!$B:$B,'PTO SUMMARY 2027'!BH11,'October 2027'!$AK:$AK) -> 0 | BV11: =BM11+BT11-BU11 -> 138.66323 | BW11: 0 | BX11: 0 | BY11: =H11 -> 13.866645 | BZ11: =SUMIF('November 2027'!$B:$B,'PTO SUMMARY 2027'!BM11,'November 2027'!$AK:$AK) -> 0 | CA11: =BV11+BY11-BZ11 -> 152.52987 | CB11: 0 | CC11: 0 | CD11: =H11 -> 13.866645 | CE11: =SUMIF('December 2027'!$B:$B,'PTO SUMMARY 2027'!$B:$B,'December 2027'!$AK:$AK) -> 0 | CF11: =CA11+CD11-CE11 -> 166.39652 | CG11: 0 | CH11: 0 | CI11: 0 | CJ11: 0 | CK11: 0 | CL11: 0 | CM11: 0 | CN11: =CK11+CL11-CM11 -> 0
A12: Boehm, Holly | B12: A1YX | C12: APC | D12: Y | E12: OWA | F12: OCmid | G12: 1 | H12: 0 | I12: 0 | J12: 0 | K12: 0 | L12: 0 | M12: 0 | N12: =H12 -> 0 | O12: =SUMIF('January 2027'!$B:$B,'PTO SUMMARY 2027'!B12,'January 2027'!$AK:$AK) -> 0 | P12: =L12+M12+N12-O12 -> 0 | Q12: 0 | R12: 0 | S12: =H12 -> 0 | T12: =SUMIF('February 2027'!$B:$B,'PTO SUMMARY 2027'!G12,'February 2027'!$AK:$AK) -> 0 | U12: 0 | V12: =P12+S12-T12 -> 0 | W12: 0 | X12: 0 | Y12: =H12 -> 0 | Z12: =SUMIF('March 2027'!$B:$B,'PTO SUMMARY 2027'!M12,'March 2027'!$AK:$AK) -> 0 | AA12: =V12+Y12-Z12 -> 0 | AB12: 0 | AC12: 0 | AD12: 0 | AE12: =K12-AD12 -> 0 | AF12: 0 | AG12: =AE12-AF12 -> 0 | AH12: =H12 -> 0 | AI12: =SUMIF('April 2027'!$B:$B,'PTO SUMMARY 2027'!V12,'April 2027'!$AK:$AK) -> 0 | AJ12: =AA12+AH12-AI12 -> 0 | AK12: 0 | AL12: 0 | AM12: =H12 -> 0 | AN12: =SUMIF('May 2027'!$B:$B,'PTO SUMMARY 2027'!AA12,'May 2027'!$AK:$AK) -> 0 | AO12: =ROUND((AJ12+AM12-AN12),2) -> 0 | AP12: 0 | AQ12: 0 | AR12: =H12 -> 0 | AS12: =SUMIF('June 2027'!$B:$B,'PTO SUMMARY 2027'!AF12,'June 2027'!$AK:$AK) -> 0 | AT12: =AO12+AR12-AS12 -> 0 | AU12: 0 | AV12: 0 | AW12: 0 | AX12: 0 | AY12: 0 | AZ12: =AX12-AY12 -> 0 | BA12: =H12 -> 0 | BB12: =SUMIF('July 2027'!$B:$B,'PTO SUMMARY 2027'!AK12,'July 2027'!$AK:$AK) -> 0 | BC12: =AT12+BA12-BB12 -> 0 | BD12: 0 | BE12: 0 | BF12: =H12 -> 0 | BG12: =SUMIF('August 2027'!$B:$B,'PTO SUMMARY 2027'!AP12,'August 2027'!$AK:$AK) -> 0 | BH12: =BC12+BF12-BG12 -> 0 | BI12: 0 | BJ12: 0 | BK12: =H12 -> 0 | BL12: =SUMIF('September 2027'!$B:$B,'PTO SUMMARY 2027'!AU12,'September 2027'!$AK:$AK) -> 0 | BM12: =BH12+BK12-BL12 -> 0 | BN12: 0 | BO12: 0 | BP12: 0 | BQ12: 0 | BR12: 0 | BS12: =BQ12-BR12 -> 0 | BT12: =H12 -> 0 | BU12: =SUMIF('October 2027'!$B:$B,'PTO SUMMARY 2027'!BH12,'October 2027'!$AK:$AK) -> 0 | BV12: =BM12+BT12-BU12 -> 0 | BW12: 0 | BX12: 0 | BY12: =H12 -> 0 | BZ12: =SUMIF('November 2027'!$B:$B,'PTO SUMMARY 2027'!BM12,'November 2027'!$AK:$AK) -> 0 | CA12: =BV12+BY12-BZ12 -> 0 | CB12: 0 | CC12: 0 | CD12: =H12 -> 0 | CE12: =SUMIF('December 2027'!$B:$B,'PTO SUMMARY 2027'!$B:$B,'December 2027'!$AK:$AK) -> 0 | CF12: =CA12+CD12-CE12 -> 0 | CG12: 0 | CH12: 0 | CI12: 0 | CJ12: 0 | CK12: 0 | CL12: 0 | CM12: 0 | CN12: =CK12+CL12-CM12 -> 0
A13: Bondurant, Reid | B13: A1ZB | C13: APC | E13: SMA | F13: PKmid | G13: 1 | H13: =((G13*86.67)*2)*(SUMIF('Accrual Rates'!B:B,'PTO SUMMARY 2027'!B13,'Accrual Rates'!G:G)) -> 13.333313 | I13: 0 | J13: 0 | K13: 0 | L13: 0 | M13: 0 | N13: =H13 -> 13.333313 | O13: =SUMIF('January 2027'!$B:$B,'PTO SUMMARY 2027'!B13,'January 2027'!$AK:$AK) -> 0 | P13: =L13+M13+N13-O13 -> 13.333313 | Q13: 0 | R13: 0 | S13: =H13 -> 13.333313 | T13: =SUMIF('February 2027'!$B:$B,'PTO SUMMARY 2027'!G13,'February 2027'!$AK:$AK) -> 0 | U13: 0 | V13: =P13+S13-T13 -> 26.666626 | W13: 0 | X13: 0 | Y13: =H13 -> 13.333313 | Z13: =SUMIF('March 2027'!$B:$B,'PTO SUMMARY 2027'!M13,'March 2027'!$AK:$AK) -> 0 | AA13: =V13+Y13-Z13 -> 39.999938 | AB13: 0 | AC13: 0 | AD13: 0 | AE13: =K13-AD13 -> 0 | AF13: 0 | AG13: =AE13-AF13 -> 0 | AH13: =H13 -> 13.333313 | AI13: =SUMIF('April 2027'!$B:$B,'PTO SUMMARY 2027'!V13,'April 2027'!$AK:$AK) -> 0 | AJ13: =AA13+AH13-AI13 -> 53.333251 | AK13: 0 | AL13: 0 | AM13: =H13 -> 13.333313 | AN13: =SUMIF('May 2027'!$B:$B,'PTO SUMMARY 2027'!AA13,'May 2027'!$AK:$AK) -> 0 | AO13: =ROUND((AJ13+AM13-AN13),2) -> 66.67 | AP13: 0 | AQ13: 0 | AR13: =H13 -> 13.333313 | AS13: =SUMIF('June 2027'!$B:$B,'PTO SUMMARY 2027'!AF13,'June 2027'!$AK:$AK) -> 0 | AT13: =AO13+AR13-AS13 -> 80.003313 | AU13: 0 | AV13: 0 | AW13: 0 | AX13: 0 | AY13: 0 | AZ13: =AX13-AY13 -> 0 | BA13: =H13 -> 13.333313 | BB13: =SUMIF('July 2027'!$B:$B,'PTO SUMMARY 2027'!AK13,'July 2027'!$AK:$AK) -> 0 | BC13: =AT13+BA13-BB13 -> 93.336626 | BD13: 0 | BE13: 0 | BF13: =H13 -> 13.333313 | BG13: =SUMIF('August 2027'!$B:$B,'PTO SUMMARY 2027'!AP13,'August 2027'!$AK:$AK) -> 0 | BH13: =BC13+BF13-BG13 -> 106.66994 | BI13: 0 | BJ13: 0 | BK13: =H13 -> 13.333313 | BL13: =SUMIF('September 2027'!$B:$B,'PTO SUMMARY 2027'!AU13,'September 2027'!$AK:$AK) -> 0 | BM13: =BH13+BK13-BL13 -> 120.00325 | BN13: 0 | BO13: 0 | BP13: 0 | BQ13: 0 | BR13: 0 | BS13: =BQ13-BR13 -> 0 | BT13: =H13 -> 13.333313 | BU13: =SUMIF('October 2027'!$B:$B,'PTO SUMMARY 2027'!BH13,'October 2027'!$AK:$AK) -> 0 | BV13: =BM13+BT13-BU13 -> 133.33656 | BW13: 0 | BX13: 0 | BY13: =H13 -> 13.333313 | BZ13: =SUMIF('November 2027'!$B:$B,'PTO SUMMARY 2027'!BM13,'November 2027'!$AK:$AK) -> 0 | CA13: =BV13+BY13-BZ13 -> 146.66988 | CB13: 0 | CC13: 0 | CD13: =H13 -> 13.333313 | CE13: =SUMIF('December 2027'!$B:$B,'PTO SUMMARY 2027'!$B:$B,'December 2027'!$AK:$AK) -> 0 | CF13: =CA13+CD13-CE13 -> 160.00319 | CG13: 0 | CH13: 0 | CI13: 0 | CJ13: 0 | CK13: 0 | CL13: 0 | CM13: 0 | CN13: =CK13+CL13-CM13 -> 0
A14: Boyles, Sarah | B14: A3PJ | C14: MD | E14: SAM | F14: PKMD | G14: 1 | H14: =((G14*86.67)*2)*(SUMIF('Accrual Rates'!B:B,'PTO SUMMARY 2027'!B14,'Accrual Rates'!G:G)) -> 13.333313 | I14: 0 | J14: 0 | K14: 0 | L14: 0 | M14: 0 | N14: =H14 -> 13.333313 | O14: =SUMIF('January 2027'!$B:$B,'PTO SUMMARY 2027'!B14,'January 2027'!$AK:$AK) -> 0 | P14: =L14+M14+N14-O14 -> 13.333313 | Q14: 0 | R14: 0 | S14: =H14 -> 13.333313 | T14: =SUMIF('February 2027'!$B:$B,'PTO SUMMARY 2027'!G14,'February 2027'!$AK:$AK) -> 0 | U14: 0 | V14: =P14+S14-T14 -> 26.666626 | W14: 0 | X14: 0 | Y14: =H14 -> 13.333313 | Z14: =SUMIF('March 2027'!$B:$B,'PTO SUMMARY 2027'!M14,'March 2027'!$AK:$AK) -> 0 | AA14: =V14+Y14-Z14 -> 39.999938 | AB14: 0 | AC14: 0 | AD14: 0 | AE14: =K14-AD14 -> 0 | AF14: 0 | AG14: =AE14-AF14 -> 0 | AH14: =H14 -> 13.333313 | AI14: =SUMIF('April 2027'!$B:$B,'PTO SUMMARY 2027'!V14,'April 2027'!$AK:$AK) -> 0 | AJ14: =AA14+AH14-AI14 -> 53.333251 | AK14: 0 | AL14: 0 | AM14: =H14 -> 13.333313 | AN14: =SUMIF('May 2027'!$B:$B,'PTO SUMMARY 2027'!AA14,'May 2027'!$AK:$AK) -> 0 | AO14: =ROUND((AJ14+AM14-AN14),2) -> 66.67 | AP14: 0 | AQ14: 0 | AR14: =H14 -> 13.333313 | AS14: =SUMIF('June 2027'!$B:$B,'PTO SUMMARY 2027'!AF14,'June 2027'!$AK:$AK) -> 0 | AT14: =AO14+AR14-AS14 -> 80.003313 | AU14: 0 | AV14: 0 | AW14: 0 | AX14: 0 | AY14: 0 | AZ14: =AX14-AY14 -> 0 | BA14: =H14 -> 13.333313 | BB14: =SUMIF('July 2027'!$B:$B,'PTO SUMMARY 2027'!AK14,'July 2027'!$AK:$AK) -> 0 | BC14: =AT14+BA14-BB14 -> 93.336626 | BD14: 0 | BE14: 0 | BF14: =H14 -> 13.333313 | BG14: =SUMIF('August 2027'!$B:$B,'PTO SUMMARY 2027'!AP14,'August 2027'!$AK:$AK) -> 0 | BH14: =BC14+BF14-BG14 -> 106.66994 | BI14: 0 | BJ14: 0 | BK14: =H14 -> 13.333313 | BL14: =SUMIF('September 2027'!$B:$B,'PTO SUMMARY 2027'!AU14,'September 2027'!$AK:$AK) -> 0 | BM14: =BH14+BK14-BL14 -> 120.00325 | BN14: 0 | BO14: 0 | BP14: 0 | BQ14: 0 | BR14: 0 | BS14: =BQ14-BR14 -> 0 | BT14: =H14 -> 13.333313 | BU14: =SUMIF('October 2027'!$B:$B,'PTO SUMMARY 2027'!BH14,'October 2027'!$AK:$AK) -> 0 | BV14: =BM14+BT14-BU14 -> 133.33656 | BW14: 0 | BX14: 0 | BY14: =H14 -> 13.333313 | BZ14: =SUMIF('November 2027'!$B:$B,'PTO SUMMARY 2027'!BM14,'November 2027'!$AK:$AK) -> 0 | CA14: =BV14+BY14-BZ14 -> 146.66988 | CB14: 0 | CC14: 0 | CD14: =H14 -> 13.333313 | CE14: =SUMIF('December 2027'!$B:$B,'PTO SUMMARY 2027'!$B:$B,'December 2027'!$AK:$AK) -> 0 | CF14: =CA14+CD14-CE14 -> 160.00319 | CG14: 0 | CH14: 0 | CI14: 0 | CJ14: 0 | CK14: 0 | CL14: 0 | CM14: 0 | CN14: =CK14+CL14-CM14 -> 0
A15: Braun, Andrew | B15: A3NB | C15: MD | E15: SAM | F15: GW | G15: 1 | H15: =((G15*86.67)*2)*(SUMIF('Accrual Rates'!B:B,'PTO SUMMARY 2027'!B15,'Accrual Rates'!G:G)) -> 15.999975 | I15: 0 | J15: 0 | K15: 0 | L15: 0 | M15: 0 | N15: =H15 -> 15.999975 | O15: =SUMIF('January 2027'!$B:$B,'PTO SUMMARY 2027'!B15,'January 2027'!$AK:$AK) -> 0 | P15: =L15+M15+N15-O15 -> 15.999975 | Q15: 0 | R15: 0 | S15: =H15 -> 15.999975 | T15: =SUMIF('February 2027'!$B:$B,'PTO SUMMARY 2027'!G15,'February 2027'!$AK:$AK) -> 0 | U15: 0 | V15: =P15+S15-T15 -> 31.999951 | W15: 0 | X15: 0 | Y15: =H15 -> 15.999975 | Z15: =SUMIF('March 2027'!$B:$B,'PTO SUMMARY 2027'!M15,'March 2027'!$AK:$AK) -> 0 | AA15: =V15+Y15-Z15 -> 47.999926 | AB15: 0 | AC15: 0 | AD15: 0 | AE15: =K15-AD15 -> 0 | AF15: 0 | AG15: =AE15-AF15 -> 0 | AH15: =H15 -> 15.999975 | AI15: =SUMIF('April 2027'!$B:$B,'PTO SUMMARY 2027'!V15,'April 2027'!$AK:$AK) -> 0 | AJ15: =AA15+AH15-AI15 -> 63.999901 | AK15: 0 | AL15: 0 | AM15: =H15 -> 15.999975 | AN15: =SUMIF('May 2027'!$B:$B,'PTO SUMMARY 2027'!AA15,'May 2027'!$AK:$AK) -> 0 | AO15: =ROUND((AJ15+AM15-AN15),2) -> 80 | AP15: 0 | AQ15: 0 | AR15: =H15 -> 15.999975 | AS15: =SUMIF('June 2027'!$B:$B,'PTO SUMMARY 2027'!AF15,'June 2027'!$AK:$AK) -> 0 | AT15: =AO15+AR15-AS15 -> 95.999975 | AU15: 0 | AV15: 0 | AW15: 0 | AX15: 0 | AY15: 0 | AZ15: =AX15-AY15 -> 0 | BA15: =H15 -> 15.999975 | BB15: =SUMIF('July 2027'!$B:$B,'PTO SUMMARY 2027'!AK15,'July 2027'!$AK:$AK) -> 0 | BC15: =AT15+BA15-BB15 -> 111.99995 | BD15: 0 | BE15: 0 | BF15: =H15 -> 15.999975 | BG15: =SUMIF('August 2027'!$B:$B,'PTO SUMMARY 2027'!AP15,'August 2027'!$AK:$AK) -> 0 | BH15: =BC15+BF15-BG15 -> 127.99993 | BI15: 0 | BJ15: 0 | BK15: =H15 -> 15.999975 | BL15: =SUMIF('September 2027'!$B:$B,'PTO SUMMARY 2027'!AU15,'September 2027'!$AK:$AK) -> 0 | BM15: =BH15+BK15-BL15 -> 143.9999 | BN15: 0 | BO15: 0 | BP15: 0 | BQ15: 0 | BR15: 0 | BS15: =BQ15-BR15 -> 0 | BT15: =H15 -> 15.999975 | BU15: =SUMIF('October 2027'!$B:$B,'PTO SUMMARY 2027'!BH15,'October 2027'!$AK:$AK) -> 0 | BV15: =BM15+BT15-BU15 -> 159.99988 | BW15: 0 | BX15: 0 | BY15: =H15 -> 15.999975 | BZ15: =SUMIF('November 2027'!$B:$B,'PTO SUMMARY 2027'!BM15,'November 2027'!$AK:$AK) -> 0 | CA15: =BV15+BY15-BZ15 -> 175.99985 | CB15: 0 | CC15: 0 | CD15: =H15 -> 15.999975 | CE15: =SUMIF('December 2027'!$B:$B,'PTO SUMMARY 2027'!$B:$B,'December 2027'!$AK:$AK) -> 0 | CF15: =CA15+CD15-CE15 -> 191.99983 | CG15: 0 | CH15: 0 | CI15: 0 | CJ15: 0 | CK15: 0 | CL15: 0 | CM15: 0 | CN15: =CK15+CL15-CM15 -> 0
A16: Brennan, Thomas | B16: A209 | C16: MD | D16: Y | E16: OWM | F16: PKMD | G16: 1 | H16: 0 | I16: 0 | J16: 0 | K16: 0 | L16: 0 | M16: 0 | N16: =H16 -> 0 | O16: =SUMIF('January 2027'!$B:$B,'PTO SUMMARY 2027'!B16,'January 2027'!$AK:$AK) -> 0 | P16: =L16+M16+N16-O16 -> 0 | Q16: 0 | R16: 0 | S16: =H16 -> 0 | T16: =SUMIF('February 2027'!$B:$B,'PTO SUMMARY 2027'!G16,'February 2027'!$AK:$AK) -> 0 | U16: 0 | V16: =P16+S16-T16 -> 0 | W16: 0 | X16: 0 | Y16: =H16 -> 0 | Z16: =SUMIF('March 2027'!$B:$B,'PTO SUMMARY 2027'!M16,'March 2027'!$AK:$AK) -> 0 | AA16: =V16+Y16-Z16 -> 0 | AB16: 0 | AC16: 0 | AD16: 0 | AE16: =K16-AD16 -> 0 | AF16: 0 | AG16: =AE16-AF16 -> 0 | AH16: =H16 -> 0 | AI16: =SUMIF('April 2027'!$B:$B,'PTO SUMMARY 2027'!V16,'April 2027'!$AK:$AK) -> 0 | AJ16: =AA16+AH16-AI16 -> 0 | AK16: 0 | AL16: 0 | AM16: =H16 -> 0 | AN16: =SUMIF('May 2027'!$B:$B,'PTO SUMMARY 2027'!AA16,'May 2027'!$AK:$AK) -> 0 | AO16: =ROUND((AJ16+AM16-AN16),2) -> 0 | AP16: 0 | AQ16: 0 | AR16: =H16 -> 0 | AS16: =SUMIF('June 2027'!$B:$B,'PTO SUMMARY 2027'!AF16,'June 2027'!$AK:$AK) -> 0 | AT16: =AO16+AR16-AS16 -> 0 | AU16: 0 | AV16: 0 | AW16: 0 | AX16: 0 | AY16: 0 | AZ16: =AX16-AY16 -> 0 | BA16: =H16 -> 0 | BB16: =SUMIF('July 2027'!$B:$B,'PTO SUMMARY 2027'!AK16,'July 2027'!$AK:$AK) -> 0 | BC16: =AT16+BA16-BB16 -> 0 | BD16: 0 | BE16: 0 | BF16: =H16 -> 0 | BG16: =SUMIF('August 2027'!$B:$B,'PTO SUMMARY 2027'!AP16,'August 2027'!$AK:$AK) -> 0 | BH16: =BC16+BF16-BG16 -> 0 | BI16: 0 | BJ16: 0 | BK16: =H16 -> 0 | BL16: =SUMIF('September 2027'!$B:$B,'PTO SUMMARY 2027'!AU16,'September 2027'!$AK:$AK) -> 0 | BM16: =BH16+BK16-BL16 -> 0 | BN16: 0 | BO16: 0 | BP16: 0 | BQ16: 0 | BR16: 0 | BS16: =BQ16-BR16 -> 0 | BT16: =H16 -> 0 | BU16: =SUMIF('October 2027'!$B:$B,'PTO SUMMARY 2027'!BH16,'October 2027'!$AK:$AK) -> 0 | BV16: =BM16+BT16-BU16 -> 0 | BW16: 0 | BX16: 0 | BY16: =H16 -> 0 | BZ16: =SUMIF('November 2027'!$B:$B,'PTO SUMMARY 2027'!BM16,'November 2027'!$AK:$AK) -> 0 | CA16: =BV16+BY16-BZ16 -> 0 | CB16: 0 | CC16: 0 | CD16: =H16 -> 0 | CE16: =SUMIF('December 2027'!$B:$B,'PTO SUMMARY 2027'!$B:$B,'December 2027'!$AK:$AK) -> 0 | CF16: =CA16+CD16-CE16 -> 0 | CG16: 0 | CH16: 0 | CI16: 0 | CJ16: 0 | CK16: 0 | CL16: 0 | CM16: 0 | CN16: =CK16+CL16-CM16 -> 0
A17: Bronson, Joline | B17: A20L | C17: MD | D17: Y | E17: OWM | F17: OCMD | G17: 0.87 | H17: 0 | I17: 0 | J17: 0 | K17: 0 | L17: 0 | M17: 0 | N17: =H17 -> 0 | O17: =SUMIF('January 2027'!$B:$B,'PTO SUMMARY 2027'!B17,'January 2027'!$AK:$AK) -> 0 | P17: =L17+M17+N17-O17 -> 0 | Q17: 0 | R17: 0 | S17: =H17 -> 0 | T17: =SUMIF('February 2027'!$B:$B,'PTO SUMMARY 2027'!G17,'February 2027'!$AK:$AK) -> 0 | U17: 0 | V17: =P17+S17-T17 -> 0 | W17: 0 | X17: 0 | Y17: =H17 -> 0 | Z17: =SUMIF('March 2027'!$B:$B,'PTO SUMMARY 2027'!M17,'March 2027'!$AK:$AK) -> 0 | AA17: =V17+Y17-Z17 -> 0 | AB17: 0 | AC17: 0 | AD17: 0 | AE17: =K17-AD17 -> 0 | AF17: 0 | AG17: =AE17-AF17 -> 0 | AH17: =H17 -> 0 | AI17: =SUMIF('April 2027'!$B:$B,'PTO SUMMARY 2027'!V17,'April 2027'!$AK:$AK) -> 0 | AJ17: =AA17+AH17-AI17 -> 0 | AK17: 0 | AL17: 0 | AM17: =H17 -> 0 | AN17: =SUMIF('May 2027'!$B:$B,'PTO SUMMARY 2027'!AA17,'May 2027'!$AK:$AK) -> 0 | AO17: =ROUND((AJ17+AM17-AN17),2) -> 0 | AP17: 0 | AQ17: 0 | AR17: =H17 -> 0 | AS17: =SUMIF('June 2027'!$B:$B,'PTO SUMMARY 2027'!AF17,'June 2027'!$AK:$AK) -> 0 | AT17: =AO17+AR17-AS17 -> 0 | AU17: 0 | AV17: 0 | AW17: 0 | AX17: 0 | AY17: 0 | AZ17: =AX17-AY17 -> 0 | BA17: =H17 -> 0 | BB17: =SUMIF('July 2027'!$B:$B,'PTO SUMMARY 2027'!AK17,'July 2027'!$AK:$AK) -> 0 | BC17: =AT17+BA17-BB17 -> 0 | BD17: 0 | BE17: 0 | BF17: =H17 -> 0 | BG17: =SUMIF('August 2027'!$B:$B,'PTO SUMMARY 2027'!AP17,'August 2027'!$AK:$AK) -> 0 | BH17: =BC17+BF17-BG17 -> 0 | BI17: 0 | BJ17: 0 | BK17: =H17 -> 0 | BL17: =SUMIF('September 2027'!$B:$B,'PTO SUMMARY 2027'!AU17,'September 2027'!$AK:$AK) -> 0 | BM17: =BH17+BK17-BL17 -> 0 | BN17: 0 | BO17: 0 | BP17: 0 | BQ17: 0 | BR17: 0 | BS17: =BQ17-BR17 -> 0 | BT17: =H17 -> 0 | BU17: =SUMIF('October 2027'!$B:$B,'PTO SUMMARY 2027'!BH17,'October 2027'!$AK:$AK) -> 0 | BV17: =BM17+BT17-BU17 -> 0 | BW17: 0 | BX17: 0 | BY17: =H17 -> 0 | BZ17: =SUMIF('November 2027'!$B:$B,'PTO SUMMARY 2027'!BM17,'November 2027'!$AK:$AK) -> 0 | CA17: =BV17+BY17-BZ17 -> 0 | CB17: 0 | CC17: 0 | CD17: =H17 -> 0 | CE17: =SUMIF('December 2027'!$B:$B,'PTO SUMMARY 2027'!$B:$B,'December 2027'!$AK:$AK) -> 0 | CF17: =CA17+CD17-CE17 -> 0 | CG17: 0 | CH17: 0 | CI17: 0 | CJ17: 0 | CK17: 0 | CL17: 0 | CM17: 0 | CN17: =CK17+CL17-CM17 -> 0
A18: Burgoine, Gary | B18: A21A | C18: MD | D18: Y | E18: OWM | F18: TN | G18: 1 | H18: 0 | I18: 0 | J18: 0 | K18: 0 | L18: 0 | M18: 0 | N18: =H18 -> 0 | O18: =SUMIF('January 2027'!$B:$B,'PTO SUMMARY 2027'!B18,'January 2027'!$AK:$AK) -> 0 | P18: =L18+M18+N18-O18 -> 0 | Q18: 0 | R18: 0 | S18: =H18 -> 0 | T18: =SUMIF('February 2027'!$B:$B,'PTO SUMMARY 2027'!G18,'February 2027'!$AK:$AK) -> 0 | U18: 0 | V18: =P18+S18-T18 -> 0 | W18: 0 | X18: 0 | Y18: =H18 -> 0 | Z18: =SUMIF('March 2027'!$B:$B,'PTO SUMMARY 2027'!M18,'March 2027'!$AK:$AK) -> 0 | AA18: =V18+Y18-Z18-U18 -> 0 | AB18: 0 | AC18: 0 | AD18: 0 | AE18: =K18-AD18 -> 0 | AF18: 0 | AG18: =AE18-AF18 -> 0 | AH18: =H18 -> 0 | AI18: =SUMIF('April 2027'!$B:$B,'PTO SUMMARY 2027'!V18,'April 2027'!$AK:$AK) -> 0 | AJ18: =AA18+AH18-AI18 -> 0 | AK18: 0 | AL18: 0 | AM18: =H18 -> 0 | AN18: =SUMIF('May 2027'!$B:$B,'PTO SUMMARY 2027'!AA18,'May 2027'!$AK:$AK) -> 0 | AO18: =ROUND((AJ18+AM18-AN18),2) -> 0 | AP18: 0 | AQ18: 0 | AR18: =H18 -> 0 | AS18: =SUMIF('June 2027'!$B:$B,'PTO SUMMARY 2027'!AF18,'June 2027'!$AK:$AK) -> 0 | AT18: =AO18+AR18-AS18 -> 0 | AU18: 0 | AV18: 0 | AW18: 0 | AX18: 0 | AY18: 0 | AZ18: =AX18-AY18 -> 0 | BA18: =H18 -> 0 | BB18: =SUMIF('July 2027'!$B:$B,'PTO SUMMARY 2027'!AK18,'July 2027'!$AK:$AK) -> 0 | BC18: =AT18+BA18-BB18 -> 0 | BD18: 0 | BE18: 0 | BF18: =H18 -> 0 | BG18: =SUMIF('August 2027'!$B:$B,'PTO SUMMARY 2027'!AP18,'August 2027'!$AK:$AK) -> 0 | BH18: =BC18+BF18-BG18 -> 0 | BI18: 0 | BJ18: 0 | BK18: =H18 -> 0 | BL18: =SUMIF('September 2027'!$B:$B,'PTO SUMMARY 2027'!AU18,'September 2027'!$AK:$AK) -> 0 | BM18: =BH18+BK18-BL18 -> 0 | BN18: 0 | BO18: 0 | BP18: 0 | BQ18: 0 | BR18: 0 | BS18: =BQ18-BR18 -> 0 | BT18: =H18 -> 0 | BU18: =SUMIF('October 2027'!$B:$B,'PTO SUMMARY 2027'!BH18,'October 2027'!$AK:$AK) -> 0 | BV18: =BM18+BT18-BU18 -> 0 | BW18: 0 | BX18: 0 | BY18: =H18 -> 0 | BZ18: =SUMIF('November 2027'!$B:$B,'PTO SUMMARY 2027'!BM18,'November 2027'!$AK:$AK) -> 0 | CA18: =BV18+BY18-BZ18 -> 0 | CB18: 0 | CC18: 0 | CD18: =H18 -> 0 | CE18: =SUMIF('December 2027'!$B:$B,'PTO SUMMARY 2027'!$B:$B,'December 2027'!$AK:$AK) -> 0 | CF18: =CA18+CD18-CE18 -> 0 | CG18: 0 | CH18: 0 | CI18: 0 | CJ18: 0 | CK18: 0 | CL18: 0 | CM18: 0 | CN18: =CK18+CL18-CM18 -> 0
A19: Burke, Jamie | B19: A21B | C19: APC | E19: SMA | F19: GW | G19: 0.75 | H19: =((G19*86.67)*2)*(SUMIF('Accrual Rates'!B:B,'PTO SUMMARY 2027'!B19,'Accrual Rates'!G:G)) -> 12.99998 | I19: 0 | J19: 0 | K19: 0 | L19: 0 | M19: 0 | N19: =H19 -> 12.99998 | O19: =SUMIF('January 2027'!$B:$B,'PTO SUMMARY 2027'!B19,'January 2027'!$AK:$AK) -> 15 | P19: =L19+M19+N19-O19 -> -2.00002 | Q19: 0 | R19: 0 | S19: =H19 -> 12.99998 | T19: =SUMIF('February 2027'!$B:$B,'PTO SUMMARY 2027'!G19,'February 2027'!$AK:$AK) -> 0 | U19: 0 | V19: =P19+S19-T19 -> 10.99996 | W19: 0 | X19: 0 | Y19: =H19 -> 12.99998 | Z19: =SUMIF('March 2027'!$B:$B,'PTO SUMMARY 2027'!M19,'March 2027'!$AK:$AK) -> 0 | AA19: =V19+Y19-Z19 -> 23.99994 | AB19: 0 | AC19: 0 | AD19: 0 | AE19: =K19-AD19 -> 0 | AF19: 0 | AG19: =AE19-AF19 -> 0 | AH19: =H19 -> 12.99998 | AI19: =SUMIF('April 2027'!$B:$B,'PTO SUMMARY 2027'!V19,'April 2027'!$AK:$AK) -> 0 | AJ19: =AA19+AH19-AI19 -> 36.99992 | AK19: 0 | AL19: 0 | AM19: =H19 -> 12.99998 | AN19: =SUMIF('May 2027'!$B:$B,'PTO SUMMARY 2027'!AA19,'May 2027'!$AK:$AK) -> 0 | AO19: =ROUND((AJ19+AM19-AN19),2) -> 50 | AP19: 0 | AQ19: 0 | AR19: =H19 -> 12.99998 | AS19: =SUMIF('June 2027'!$B:$B,'PTO SUMMARY 2027'!AF19,'June 2027'!$AK:$AK) -> 0 | AT19: =AO19+AR19-AS19 -> 62.99998 | AU19: 0 | AV19: 0 | AW19: 0 | AX19: 0 | AY19: 0 | AZ19: =AX19-AY19 -> 0 | BA19: =H19 -> 12.99998 | BB19: =SUMIF('July 2027'!$B:$B,'PTO SUMMARY 2027'!AK19,'July 2027'!$AK:$AK) -> 0 | BC19: =AT19+BA19-BB19 -> 75.99996 | BD19: 0 | BE19: 0 | BF19: =H19 -> 12.99998 | BG19: =SUMIF('August 2027'!$B:$B,'PTO SUMMARY 2027'!AP19,'August 2027'!$AK:$AK) -> 0 | BH19: =BC19+BF19-BG19 -> 88.99994 | BI19: 0 | BJ19: 0 | BK19: =H19 -> 12.99998 | BL19: =SUMIF('September 2027'!$B:$B,'PTO SUMMARY 2027'!AU19,'September 2027'!$AK:$AK) -> 0 | BM19: =BH19+BK19-BL19 -> 101.99992 | BN19: 0 | BO19: 0 | BP19: 0 | BQ19: 0 | BR19: 0 | BS19: =BQ19-BR19 -> 0 | BT19: =H19 -> 12.99998 | BU19: =SUMIF('October 2027'!$B:$B,'PTO SUMMARY 2027'!BH19,'October 2027'!$AK:$AK) -> 0 | BV19: =BM19+BT19-BU19 -> 114.9999 | BW19: 0 | BX19: 0 | BY19: =H19 -> 12.99998 | BZ19: =SUMIF('November 2027'!$B:$B,'PTO SUMMARY 2027'!BM19,'November 2027'!$AK:$AK) -> 0 | CA19: =BV19+BY19-BZ19 -> 127.99988 | CB19: 0 | CC19: 0 | CD19: =H19 -> 12.99998 | CE19: =SUMIF('December 2027'!$B:$B,'PTO SUMMARY 2027'!$B:$B,'December 2027'!$AK:$AK) -> 0 | CF19: =CA19+CD19-CE19 -> 140.99986 | CG19: 0 | CH19: 0 | CI19: 0 | CJ19: 0 | CK19: 0 | CL19: 0 | CM19: 0 | CN19: =CK19+CL19-CM19 -> 0
A20: Carlyle, Marni | B20: A22L | C20: MD | D20: Y | E20: MFM | F20: PKMD | G20: 1 | H20: 0 | I20: 0 | J20: 0 | K20: 0 | L20: 0 | M20: 0 | N20: =H20 -> 0 | O20: =SUMIF('January 2027'!$B:$B,'PTO SUMMARY 2027'!B20,'January 2027'!$AK:$AK) -> 0 | P20: =L20+M20+N20-O20 -> 0 | Q20: 0 | R20: 0 | S20: =H20 -> 0 | T20: =SUMIF('February 2027'!$B:$B,'PTO SUMMARY 2027'!G20,'February 2027'!$AK:$AK) -> 0 | U20: 0 | V20: =P20+S20-T20 -> 0 | W20: 0 | X20: 0 | Y20: =H20 -> 0 | Z20: =SUMIF('March 2027'!$B:$B,'PTO SUMMARY 2027'!M20,'March 2027'!$AK:$AK) -> 0 | AA20: =V20+Y20-Z20 -> 0 | AB20: 0 | AC20: 0 | AD20: 0 | AE20: =K20-AD20 -> 0 | AF20: 0 | AG20: =AE20-AF20 -> 0 | AH20: =H20 -> 0 | AI20: =SUMIF('April 2027'!$B:$B,'PTO SUMMARY 2027'!V20,'April 2027'!$AK:$AK) -> 0 | AJ20: =AA20+AH20-AI20 -> 0 | AK20: 0 | AL20: 0 | AM20: =H20 -> 0 | AN20: =SUMIF('May 2027'!$B:$B,'PTO SUMMARY 2027'!AA20,'May 2027'!$AK:$AK) -> 0 | AO20: =ROUND((AJ20+AM20-AN20),2) -> 0 | AP20: 0 | AQ20: 0 | AR20: =H20 -> 0 | AS20: =SUMIF('June 2027'!$B:$B,'PTO SUMMARY 2027'!AF20,'June 2027'!$AK:$AK) -> 0 | AT20: =AO20+AR20-AS20 -> 0 | AU20: 0 | AV20: 0 | AW20: 0 | AX20: 0 | AY20: 0 | AZ20: =AX20-AY20 -> 0 | BA20: =H20 -> 0 | BB20: =SUMIF('July 2027'!$B:$B,'PTO SUMMARY 2027'!AK20,'July 2027'!$AK:$AK) -> 0 | BC20: =AT20+BA20-BB20 -> 0 | BD20: 0 | BE20: 0 | BF20: =H20 -> 0 | BG20: =SUMIF('August 2027'!$B:$B,'PTO SUMMARY 2027'!AP20,'August 2027'!$AK:$AK) -> 0 | BH20: =BC20+BF20-BG20 -> 0 | BI20: 0 | BJ20: 0 | BK20: =H20 -> 0 | BL20: =SUMIF('September 2027'!$B:$B,'PTO SUMMARY 2027'!AU20,'September 2027'!$AK:$AK) -> 0 | BM20: =BH20+BK20-BL20 -> 0 | BN20: 0 | BO20: 0 | BP20: 0 | BQ20: 0 | BR20: 0 | BS20: =BQ20-BR20 -> 0 | BT20: =H20 -> 0 | BU20: =SUMIF('October 2027'!$B:$B,'PTO SUMMARY 2027'!BH20,'October 2027'!$AK:$AK) -> 0 | BV20: =BM20+BT20-BU20 -> 0 | BW20: 0 | BX20: 0 | BY20: =H20 -> 0 | BZ20: =SUMIF('November 2027'!$B:$B,'PTO SUMMARY 2027'!BM20,'November 2027'!$AK:$AK) -> 0 | CA20: =BV20+BY20-BZ20 -> 0 | CB20: 0 | CC20: 0 | CD20: =H20 -> 0 | CE20: =SUMIF('December 2027'!$B:$B,'PTO SUMMARY 2027'!$B:$B,'December 2027'!$AK:$AK) -> 0 | CF20: =CA20+CD20-CE20 -> 0 | CG20: 0 | CH20: 0 | CI20: 0 | CJ20: 0 | CK20: 0 | CL20: 0 | CM20: 0 | CN20: =CK20+CL20-CM20 -> 0
A21: Chick, Rhonda | B21: A23E | C21: APC | E21: SMA | F21: PKmid | G21: 0.8 | H21: =((G21*86.67)*2)*(SUMIF('Accrual Rates'!B:B,'PTO SUMMARY 2027'!B21,'Accrual Rates'!G:G)) -> 13.866645 | I21: 0 | J21: 0 | K21: 0 | L21: 0 | M21: 0 | N21: =H21 -> 13.866645 | O21: =SUMIF('January 2027'!$B:$B,'PTO SUMMARY 2027'!B21,'January 2027'!$AK:$AK) -> 0 | P21: =L21+M21+N21-O21 -> 13.866645 | Q21: 0 | R21: 0 | S21: =H21 -> 13.866645 | T21: =SUMIF('February 2027'!$B:$B,'PTO SUMMARY 2027'!G21,'February 2027'!$AK:$AK) -> 0 | U21: 0 | V21: =P21+S21-T21 -> 27.733291 | W21: 0 | X21: 0 | Y21: =H21 -> 13.866645 | Z21: =SUMIF('March 2027'!$B:$B,'PTO SUMMARY 2027'!M21,'March 2027'!$AK:$AK) -> 0 | AA21: =V21+Y21-Z21 -> 41.599936 | AB21: 0 | AC21: 0 | AD21: 0 | AE21: =K21-AD21 -> 0 | AF21: 0 | AG21: =AE21-AF21 -> 0 | AH21: =H21 -> 13.866645 | AI21: =SUMIF('April 2027'!$B:$B,'PTO SUMMARY 2027'!V21,'April 2027'!$AK:$AK) -> 0 | AJ21: =AA21+AH21-AI21 -> 55.466581 | AK21: 0 | AL21: 0 | AM21: =H21 -> 13.866645 | AN21: =SUMIF('May 2027'!$B:$B,'PTO SUMMARY 2027'!AA21,'May 2027'!$AK:$AK) -> 0 | AO21: =ROUND((AJ21+AM21-AN21),2) -> 69.33 | AP21: 0 | AQ21: 0 | AR21: =H21 -> 13.866645 | AS21: =SUMIF('June 2027'!$B:$B,'PTO SUMMARY 2027'!AF21,'June 2027'!$AK:$AK) -> 0 | AT21: =AO21+AR21-AS21 -> 83.196645 | AU21: 0 | AV21: 0 | AW21: 0 | AX21: 0 | AY21: 0 | AZ21: =AX21-AY21 -> 0 | BA21: =H21 -> 13.866645 | BB21: =SUMIF('July 2027'!$B:$B,'PTO SUMMARY 2027'!AK21,'July 2027'!$AK:$AK) -> 0 | BC21: =AT21+BA21-BB21 -> 97.063291 | BD21: 0 | BE21: 0 | BF21: =H21 -> 13.866645 | BG21: =SUMIF('August 2027'!$B:$B,'PTO SUMMARY 2027'!AP21,'August 2027'!$AK:$AK) -> 0 | BH21: =BC21+BF21-BG21 -> 110.92994 | BI21: 0 | BJ21: 0 | BK21: =H21 -> 13.866645 | BL21: =SUMIF('September 2027'!$B:$B,'PTO SUMMARY 2027'!AU21,'September 2027'!$AK:$AK) -> 0 | BM21: =BH21+BK21-BL21 -> 124.79658 | BN21: 0 | BO21: 0 | BP21: 0 | BQ21: 0 | BR21: 0 | BS21: =BQ21-BR21 -> 0 | BT21: =H21 -> 13.866645 | BU21: =SUMIF('October 2027'!$B:$B,'PTO SUMMARY 2027'!BH21,'October 2027'!$AK:$AK) -> 0 | BV21: =BM21+BT21-BU21 -> 138.66323 | BW21: 0 | BX21: 0 | BY21: =H21 -> 13.866645 | BZ21: =SUMIF('November 2027'!$B:$B,'PTO SUMMARY 2027'!BM21,'November 2027'!$AK:$AK) -> 0 | CA21: =BV21+BY21-BZ21 -> 152.52987 | CB21: 0 | CC21: 0 | CD21: =H21 -> 13.866645 | CE21: =SUMIF('December 2027'!$B:$B,'PTO SUMMARY 2027'!$B:$B,'December 2027'!$AK:$AK) -> 0 | CF21: =CA21+CD21-CE21 -> 166.39652 | CG21: 0 | CH21: 0 | CI21: 0 | CJ21: 0 | CK21: 0 | CL21: 0 | CM21: 0 | CN21: =CK21+CL21-CM21 -> 0
A22: Cohen-MacGill, Misra | B22: A240 | C22: APC | E22: SMA | F22: OCmid | G22: 1 | H22: =((G22*86.67)*2)*(SUMIF('Accrual Rates'!B:B,'PTO SUMMARY 2027'!B22,'Accrual Rates'!G:G)) -> 17.333307 | I22: 0 | J22: 0 | K22: 0 | L22: 0 | M22: 0 | N22: =H22 -> 17.333307 | O22: =SUMIF('January 2027'!$B:$B,'PTO SUMMARY 2027'!B22,'January 2027'!$AK:$AK) -> 0 | P22: =L22+M22+N22-O22 -> 17.333307 | Q22: 0 | R22: 0 | S22: =H22 -> 17.333307 | T22: =SUMIF('February 2027'!$B:$B,'PTO SUMMARY 2027'!G22,'February 2027'!$AK:$AK) -> 0 | U22: 0 | V22: =P22+S22-T22 -> 34.666613 | W22: 0 | X22: 0 | Y22: =H22 -> 17.333307 | Z22: =SUMIF('March 2027'!$B:$B,'PTO SUMMARY 2027'!M22,'March 2027'!$AK:$AK) -> 0 | AA22: =V22+Y22-Z22 -> 51.99992 | AB22: 0 | AC22: 0 | AD22: 0 | AE22: =K22-AD22 -> 0 | AF22: 0 | AG22: =AE22-AF22 -> 0 | AH22: =H22 -> 17.333307 | AI22: =SUMIF('April 2027'!$B:$B,'PTO SUMMARY 2027'!V22,'April 2027'!$AK:$AK) -> 0 | AJ22: =AA22+AH22-AI22 -> 69.333227 | AK22: 0 | AL22: 0 | AM22: =H22 -> 17.333307 | AN22: =SUMIF('May 2027'!$B:$B,'PTO SUMMARY 2027'!AA22,'May 2027'!$AK:$AK) -> 0 | AO22: =ROUND((AJ22+AM22-AN22),2) -> 86.67 | AP22: 0 | AQ22: 0 | AR22: =H22 -> 17.333307 | AS22: =SUMIF('June 2027'!$B:$B,'PTO SUMMARY 2027'!AF22,'June 2027'!$AK:$AK) -> 0 | AT22: =AO22+AR22-AS22 -> 104.00331 | AU22: 0 | AV22: 0 | AW22: 0 | AX22: 0 | AY22: 0 | AZ22: =AX22-AY22 -> 0 | BA22: =H22 -> 17.333307 | BB22: =SUMIF('July 2027'!$B:$B,'PTO SUMMARY 2027'!AK22,'July 2027'!$AK:$AK) -> 0 | BC22: =AT22+BA22-BB22 -> 121.33661 | BD22: 0 | BE22: 0 | BF22: =H22 -> 17.333307 | BG22: =SUMIF('August 2027'!$B:$B,'PTO SUMMARY 2027'!AP22,'August 2027'!$AK:$AK) -> 0 | BH22: =BC22+BF22-BG22 -> 138.66992 | BI22: 0 | BJ22: 0 | BK22: =H22 -> 17.333307 | BL22: =SUMIF('September 2027'!$B:$B,'PTO SUMMARY 2027'!AU22,'September 2027'!$AK:$AK) -> 0 | BM22: =BH22+BK22-BL22 -> 156.00323 | BN22: 0 | BO22: 0 | BP22: 0 | BQ22: 0 | BR22: 0 | BS22: =BQ22-BR22 -> 0 | BT22: =H22 -> 17.333307 | BU22: =SUMIF('October 2027'!$B:$B,'PTO SUMMARY 2027'!BH22,'October 2027'!$AK:$AK) -> 0 | BV22: =BM22+BT22-BU22 -> 173.33653 | BW22: 0 | BX22: 0 | BY22: =H22 -> 17.333307 | BZ22: =SUMIF('November 2027'!$B:$B,'PTO SUMMARY 2027'!BM22,'November 2027'!$AK:$AK) -> 0 | CA22: =BV22+BY22-BZ22 -> 190.66984 | CB22: 0 | CC22: 0 | CD22: =H22 -> 17.333307 | CE22: =SUMIF('December 2027'!$B:$B,'PTO SUMMARY 2027'!$B:$B,'December 2027'!$AK:$AK) -> 0 | CF22: =CA22+CD22-CE22 -> 208.00315 | CG22: 0 | CH22: 0 | CI22: 0 | CJ22: 0 | CK22: 0 | CL22: 0 | CM22: 0 | CN22: =CK22+CL22-CM22 -> 0
A23: Coiner, Bobbie | B23: A241 | C23: APC | E23: SMA | F23: BH | G23: 1 | H23: =((G23*86.67)*2)*(SUMIF('Accrual Rates'!B:B,'PTO SUMMARY 2027'!B23,'Accrual Rates'!G:G)) -> 17.333307 | I23: 0 | J23: 0 | K23: 0 | L23: 0 | M23: 0 | N23: =H23 -> 17.333307 | O23: =SUMIF('January 2027'!$B:$B,'PTO SUMMARY 2027'!B23,'January 2027'!$AK:$AK) -> 0 | P23: =L23+M23+N23-O23 -> 17.333307 | Q23: 0 | R23: 0 | S23: =H23 -> 17.333307 | T23: =SUMIF('February 2027'!$B:$B,'PTO SUMMARY 2027'!G23,'February 2027'!$AK:$AK) -> 0 | U23: 0 | V23: =P23+S23-T23 -> 34.666613 | W23: 0 | X23: 0 | Y23: =H23 -> 17.333307 | Z23: =SUMIF('March 2027'!$B:$B,'PTO SUMMARY 2027'!M23,'March 2027'!$AK:$AK) -> 0 | AA23: =V23+Y23-Z23 -> 51.99992 | AB23: 0 | AC23: 0 | AD23: 0 | AE23: =K23-AD23 -> 0 | AF23: 0 | AG23: =AE23-AF23 -> 0 | AH23: =H23 -> 17.333307 | AI23: =SUMIF('April 2027'!$B:$B,'PTO SUMMARY 2027'!V23,'April 2027'!$AK:$AK) -> 0 | AJ23: =AA23+AH23-AI23 -> 69.333227 | AK23: 0 | AL23: 0 | AM23: =H23 -> 17.333307 | AN23: =SUMIF('May 2027'!$B:$B,'PTO SUMMARY 2027'!AA23,'May 2027'!$AK:$AK) -> 0 | AO23: =ROUND((AJ23+AM23-AN23),2) -> 86.67 | AP23: 0 | AQ23: 0 | AR23: =H23 -> 17.333307 | AS23: =SUMIF('June 2027'!$B:$B,'PTO SUMMARY 2027'!AF23,'June 2027'!$AK:$AK) -> 0 | AT23: =AO23+AR23-AS23 -> 104.00331 | AU23: 0 | AV23: 0 | AW23: 0 | AX23: 0 | AY23: 0 | AZ23: =AX23-AY23 -> 0 | BA23: =H23 -> 17.333307 | BB23: =SUMIF('July 2027'!$B:$B,'PTO SUMMARY 2027'!AK23,'July 2027'!$AK:$AK) -> 0 | BC23: =AT23+BA23-BB23 -> 121.33661 | BD23: 0 | BE23: 0 | BF23: =H23 -> 17.333307 | BG23: =SUMIF('August 2027'!$B:$B,'PTO SUMMARY 2027'!AP23,'August 2027'!$AK:$AK) -> 0 | BH23: =BC23+BF23-BG23 -> 138.66992 | BI23: 0 | BJ23: 0 | BK23: =H23 -> 17.333307 | BL23: =SUMIF('September 2027'!$B:$B,'PTO SUMMARY 2027'!AU23,'September 2027'!$AK:$AK) -> 0 | BM23: =BH23+BK23-BL23 -> 156.00323 | BN23: 0 | BO23: 0 | BP23: 0 | BQ23: 0 | BR23: 0 | BS23: =BQ23-BR23 -> 0 | BT23: =H23 -> 17.333307 | BU23: =SUMIF('October 2027'!$B:$B,'PTO SUMMARY 2027'!BH23,'October 2027'!$AK:$AK) -> 0 | BV23: =BM23+BT23-BU23 -> 173.33653 | BW23: 0 | BX23: 0 | BY23: =H23 -> 17.333307 | BZ23: =SUMIF('November 2027'!$B:$B,'PTO SUMMARY 2027'!BM23,'November 2027'!$AK:$AK) -> 0 | CA23: =BV23+BY23-BZ23 -> 190.66984 | CB23: 0 | CC23: 0 | CD23: =H23 -> 17.333307 | CE23: =SUMIF('December 2027'!$B:$B,'PTO SUMMARY 2027'!$B:$B,'December 2027'!$AK:$AK) -> 0 | CF23: =CA23+CD23-CE23 -> 208.00315 | CG23: 0 | CH23: 0 | CI23: 0 | CJ23: 0 | CK23: 0 | CL23: 0 | CM23: 0 | CN23: =CK23+CL23-CM23 -> 0
A24: Cook, Jonathan | B24: A24Q | C24: MD | D24: Y | E24: OWM | F24: BR | G24: 1 | H24: 0 | I24: 0 | J24: 0 | K24: 0 | L24: 0 | M24: 0 | N24: =H24 -> 0 | O24: =SUMIF('January 2027'!$B:$B,'PTO SUMMARY 2027'!B24,'January 2027'!$AK:$AK) -> 0 | P24: =L24+M24+N24-O24 -> 0 | Q24: 0 | R24: 0 | S24: =H24 -> 0 | T24: =SUMIF('February 2027'!$B:$B,'PTO SUMMARY 2027'!G24,'February 2027'!$AK:$AK) -> 0 | U24: 0 | V24: =P24+S24-T24 -> 0 | W24: 0 | X24: 0 | Y24: =H24 -> 0 | Z24: =SUMIF('March 2027'!$B:$B,'PTO SUMMARY 2027'!M24,'March 2027'!$AK:$AK) -> 0 | AA24: =V24+Y24-Z24 -> 0 | AB24: 0 | AC24: 0 | AD24: 0 | AE24: =K24-AD24 -> 0 | AF24: 0 | AG24: =AE24-AF24 -> 0 | AH24: =H24 -> 0 | AI24: =SUMIF('April 2027'!$B:$B,'PTO SUMMARY 2027'!V24,'April 2027'!$AK:$AK) -> 0 | AJ24: =AA24+AH24-AI24 -> 0 | AK24: 0 | AL24: 0 | AM24: =H24 -> 0 | AN24: =SUMIF('May 2027'!$B:$B,'PTO SUMMARY 2027'!AA24,'May 2027'!$AK:$AK) -> 0 | AO24: =ROUND((AJ24+AM24-AN24),2) -> 0 | AP24: 0 | AQ24: 0 | AR24: =H24 -> 0 | AS24: =SUMIF('June 2027'!$B:$B,'PTO SUMMARY 2027'!AF24,'June 2027'!$AK:$AK) -> 0 | AT24: =AO24+AR24-AS24 -> 0 | AU24: 0 | AV24: 0 | AW24: 0 | AX24: 0 | AY24: 0 | AZ24: =AX24-AY24 -> 0 | BA24: =H24 -> 0 | BB24: =SUMIF('July 2027'!$B:$B,'PTO SUMMARY 2027'!AK24,'July 2027'!$AK:$AK) -> 0 | BC24: =AT24+BA24-BB24 -> 0 | BD24: 0 | BE24: 0 | BF24: =H24 -> 0 | BG24: =SUMIF('August 2027'!$B:$B,'PTO SUMMARY 2027'!AP24,'August 2027'!$AK:$AK) -> 0 | BH24: =BC24+BF24-BG24 -> 0 | BI24: 0 | BJ24: 0 | BK24: =H24 -> 0 | BL24: =SUMIF('September 2027'!$B:$B,'PTO SUMMARY 2027'!AU24,'September 2027'!$AK:$AK) -> 0 | BM24: =BH24+BK24-BL24 -> 0 | BN24: 0 | BO24: 0 | BP24: 0 | BQ24: 0 | BR24: 0 | BS24: =BQ24-BR24 -> 0 | BT24: =H24 -> 0 | BU24: =SUMIF('October 2027'!$B:$B,'PTO SUMMARY 2027'!BH24,'October 2027'!$AK:$AK) -> 0 | BV24: =BM24+BT24-BU24 -> 0 | BW24: 0 | BX24: 0 | BY24: =H24 -> 0 | BZ24: =SUMIF('November 2027'!$B:$B,'PTO SUMMARY 2027'!BM24,'November 2027'!$AK:$AK) -> 0 | CA24: =BV24+BY24-BZ24 -> 0 | CB24: 0 | CC24: 0 | CD24: =H24 -> 0 | CE24: =SUMIF('December 2027'!$B:$B,'PTO SUMMARY 2027'!$B:$B,'December 2027'!$AK:$AK) -> 0 | CF24: =CA24+CD24-CE24 -> 0 | CG24: 0 | CH24: 0 | CI24: 0 | CJ24: 0 | CK24: 0 | CL24: 0 | CM24: 0 | CN24: =CK24+CL24-CM24 -> 0
A25: Craig, Haley | B25: A3ND | C25: MD | E25: SAM | F25: OCMD | G25: 1 | H25: =((G25*86.67)*2)*(SUMIF('Accrual Rates'!B:B,'PTO SUMMARY 2027'!B25,'Accrual Rates'!G:G)) -> 15.999975 | I25: 0 | J25: 0 | K25: 0 | L25: 0 | M25: 0 | N25: =H25 -> 15.999975 | O25: =SUMIF('January 2027'!$B:$B,'PTO SUMMARY 2027'!B25,'January 2027'!$AK:$AK) -> 0 | P25: =L25+M25+N25-O25 -> 15.999975 | Q25: 0 | R25: 0 | S25: =H25 -> 15.999975 | T25: =SUMIF('February 2027'!$B:$B,'PTO SUMMARY 2027'!G25,'February 2027'!$AK:$AK) -> 0 | U25: 0 | V25: =P25+S25-T25 -> 31.999951 | W25: 0 | X25: 0 | Y25: =H25 -> 15.999975 | Z25: =SUMIF('March 2027'!$B:$B,'PTO SUMMARY 2027'!M25,'March 2027'!$AK:$AK) -> 0 | AA25: =V25+Y25-Z25 -> 47.999926 | AB25: 0 | AC25: 0 | AD25: 0 | AE25: =K25-AD25 -> 0 | AF25: 0 | AG25: =AE25-AF25 -> 0 | AH25: =H25 -> 15.999975 | AI25: =SUMIF('April 2027'!$B:$B,'PTO SUMMARY 2027'!V25,'April 2027'!$AK:$AK) -> 0 | AJ25: =AA25+AH25-AI25 -> 63.999901 | AK25: 0 | AL25: 0 | AM25: =H25 -> 15.999975 | AN25: =SUMIF('May 2027'!$B:$B,'PTO SUMMARY 2027'!AA25,'May 2027'!$AK:$AK) -> 0 | AO25: =ROUND((AJ25+AM25-AN25),2) -> 80 | AP25: 0 | AQ25: 0 | AR25: =H25 -> 15.999975 | AS25: =SUMIF('June 2027'!$B:$B,'PTO SUMMARY 2027'!AF25,'June 2027'!$AK:$AK) -> 0 | AT25: =AO25+AR25-AS25 -> 95.999975 | AU25: 0 | AV25: 0 | AW25: 0 | AX25: 0 | AY25: 0 | AZ25: =AX25-AY25 -> 0 | BA25: =H25 -> 15.999975 | BB25: =SUMIF('July 2027'!$B:$B,'PTO SUMMARY 2027'!AK25,'July 2027'!$AK:$AK) -> 0 | BC25: =AT25+BA25-BB25 -> 111.99995 | BD25: 0 | BE25: 0 | BF25: =H25 -> 15.999975 | BG25: =SUMIF('August 2027'!$B:$B,'PTO SUMMARY 2027'!AP25,'August 2027'!$AK:$AK) -> 0 | BH25: =BC25+BF25-BG25 -> 127.99993 | BI25: 0 | BJ25: 0 | BK25: =H25 -> 15.999975 | BL25: =SUMIF('September 2027'!$B:$B,'PTO SUMMARY 2027'!AU25,'September 2027'!$AK:$AK) -> 0 | BM25: =BH25+BK25-BL25 -> 143.9999 | BN25: 0 | BO25: 0 | BP25: 0 | BQ25: 0 | BR25: 0 | BS25: =BQ25-BR25 -> 0 | BT25: =H25 -> 15.999975 | BU25: =SUMIF('October 2027'!$B:$B,'PTO SUMMARY 2027'!BH25,'October 2027'!$AK:$AK) -> 0 | BV25: =BM25+BT25-BU25 -> 159.99988 | BW25: 0 | BX25: 0 | BY25: =H25 -> 15.999975 | BZ25: =SUMIF('November 2027'!$B:$B,'PTO SUMMARY 2027'!BM25,'November 2027'!$AK:$AK) -> 0 | CA25: =BV25+BY25-BZ25 -> 175.99985 | CB25: 0 | CC25: 0 | CD25: =H25 -> 15.999975 | CE25: =SUMIF('December 2027'!$B:$B,'PTO SUMMARY 2027'!$B:$B,'December 2027'!$AK:$AK) -> 0 | CF25: =CA25+CD25-CE25 -> 191.99983 | CG25: 0 | CH25: 0 | CI25: 0 | CJ25: 0 | CK25: 0 | CL25: 0 | CM25: 0 | CN25: =CK25+CL25-CM25 -> 0
A26: Diepenhorst, Lisa | B26: A274 | C26: MD | D26: Y | E26: OWM | F26: BR | G26: 1 | H26: 0 | I26: 0 | J26: 0 | K26: 0 | L26: 0 | M26: 0 | N26: =H26 -> 0 | O26: =SUMIF('January 2027'!$B:$B,'PTO SUMMARY 2027'!B26,'January 2027'!$AK:$AK) -> 0 | P26: =L26+M26+N26-O26 -> 0 | Q26: 0 | R26: 0 | S26: =H26 -> 0 | T26: =SUMIF('February 2027'!$B:$B,'PTO SUMMARY 2027'!G26,'February 2027'!$AK:$AK) -> 0 | U26: 0 | V26: =P26+S26-T26 -> 0 | W26: 0 | X26: 0 | Y26: =H26 -> 0 | Z26: =SUMIF('March 2027'!$B:$B,'PTO SUMMARY 2027'!M26,'March 2027'!$AK:$AK) -> 0 | AA26: =V26+Y26-Z26 -> 0 | AB26: 0 | AC26: 0 | AD26: 0 | AE26: =K26-AD26 -> 0 | AF26: 0 | AG26: =AE26-AF26 -> 0 | AH26: =H26 -> 0 | AI26: =SUMIF('April 2027'!$B:$B,'PTO SUMMARY 2027'!V26,'April 2027'!$AK:$AK) -> 0 | AJ26: =AA26+AH26-AI26 -> 0 | AK26: 0 | AL26: 0 | AM26: =H26 -> 0 | AN26: =SUMIF('May 2027'!$B:$B,'PTO SUMMARY 2027'!AA26,'May 2027'!$AK:$AK) -> 0 | AO26: =ROUND((AJ26+AM26-AN26),2) -> 0 | AP26: 0 | AQ26: 0 | AR26: =H26 -> 0 | AS26: =SUMIF('June 2027'!$B:$B,'PTO SUMMARY 2027'!AF26,'June 2027'!$AK:$AK) -> 0 | AT26: =AO26+AR26-AS26 -> 0 | AU26: 0 | AV26: 0 | AW26: 0 | AX26: 0 | AY26: 0 | AZ26: =AX26-AY26 -> 0 | BA26: =H26 -> 0 | BB26: =SUMIF('July 2027'!$B:$B,'PTO SUMMARY 2027'!AK26,'July 2027'!$AK:$AK) -> 0 | BC26: =AT26+BA26-BB26 -> 0 | BD26: 0 | BE26: 0 | BF26: =H26 -> 0 | BG26: =SUMIF('August 2027'!$B:$B,'PTO SUMMARY 2027'!AP26,'August 2027'!$AK:$AK) -> 0 | BH26: =BC26+BF26-BG26 -> 0 | BI26: 0 | BJ26: 0 | BK26: =H26 -> 0 | BL26: =SUMIF('September 2027'!$B:$B,'PTO SUMMARY 2027'!AU26,'September 2027'!$AK:$AK) -> 0 | BM26: =BH26+BK26-BL26 -> 0 | BN26: 0 | BO26: 0 | BP26: 0 | BQ26: 0 | BR26: 0 | BS26: =BQ26-BR26 -> 0 | BT26: =H26 -> 0 | BU26: =SUMIF('October 2027'!$B:$B,'PTO SUMMARY 2027'!BH26,'October 2027'!$AK:$AK) -> 0 | BV26: =BM26+BT26-BU26 -> 0 | BW26: 0 | BX26: 0 | BY26: =H26 -> 0 | BZ26: =SUMIF('November 2027'!$B:$B,'PTO SUMMARY 2027'!BM26,'November 2027'!$AK:$AK) -> 0 | CA26: =BV26+BY26-BZ26 -> 0 | CB26: 0 | CC26: 0 | CD26: =H26 -> 0 | CE26: =SUMIF('December 2027'!$B:$B,'PTO SUMMARY 2027'!$B:$B,'December 2027'!$AK:$AK) -> 0 | CF26: =CA26+CD26-CE26 -> 0 | CG26: 0 | CH26: 0 | CI26: 0 | CJ26: 0 | CK26: 0 | CL26: 0 | CM26: 0 | CN26: =CK26+CL26-CM26 -> 0
